Workbook

Sheet TIRURI
A2: Nr. Crt | B2: Descriere articol | C2: TOTAL | D2: 46216 | E2: 46217 | F2: 46218 | G2: 46219 | H2: 46220 | I2: 46221 | J2: PRET | K2: TOTAL | W2: PRET BIS | X2: ADAOS ml | Y2: ADAOS % | Z2: ADAOS
A3: COP 1 | B3: EPUIZAREA MECANICA A APEI CU MOTOPOMPA | C3: =SUM(D3:I3) | D3: =SUM(C39) | E3: =SUM(C71) | F3: =SUM(C103) | G3: =SUM(C135) | H3: =SUM(C167) | I3: =SUM(C199) | J3: 2.09 | K3: =SUM(C3*J3) | W3: 2.49 | X3: =SUM(W3-J3) | Y3: =SUM(X3*1/W3) | Z3: =SUM(C3*X3)
A4: COP 2 | B4: REFACERI PAVAJE LA STRAZI (TOATTE MATERIALELE, TRANSPORTURILE SI MANOPERA INCLUSE) | C4: =SUM(D4:I4) | D4: =SUM(C40) | E4: =SUM(C72) | F4: =SUM(C104) | G4: =SUM(C136) | H4: =SUM(C168) | I4: =SUM(C200) | J4: 42.12 | K4: =SUM(C4*J4) | W4: 50.03 | X4: =SUM(W4-J4) | Y4: =SUM(X4*1/W4) | Z4: =SUM(C4*X4)
A5: COP 3 | B5: REFACERI PAVAJE TROTUAR, ALEI PIETONALE (TOATE MATERIALELE, TRANSPORTURILE Sl MANOPERA INCLUSE) | C5: =SUM(D5:I5) | D5: =SUM(C41) | E5: =SUM(C73) | F5: =SUM(C105) | G5: =SUM(C137) | H5: =SUM(C169) | I5: =SUM(C201) | J5: 18.43 | K5: =SUM(C5*J5) | W5: 21.89 | X5: =SUM(W5-J5) | Y5: =SUM(X5*1/W5) | Z5: =SUM(C5*X5)
A6: COP 4 | B6: INCHIRIERE MACARA / NACELA | C6: =SUM(D6:I6) | D6: =SUM(C42) | E6: =SUM(C74) | F6: =SUM(C106) | G6: =SUM(C138) | H6: =SUM(C170) | I6: =SUM(C202) | J6: 27 | K6: =SUM(C6*J6) | W6: 31.29 | X6: =SUM(W6-J6) | Y6: =SUM(X6*1/W6) | Z6: =SUM(C6*X6)
A7: COP 5 | B7: TRANSPORT MATERIALE MASINA 1.5 T | C7: =SUM(D7:I7) | D7: =SUM(C43) | E7: =SUM(C75) | F7: =SUM(C107) | G7: =SUM(C139) | H7: =SUM(C171) | I7: =SUM(C203) | J7: 0.41 | K7: =SUM(C7*J7) | W7: 0.62 | X7: =SUM(W7-J7) | Y7: =SUM(X7*1/W7) | Z7: =SUM(C7*X7)
A8: COP 6 | B8: TRANSPORT MATERIALE MASINA 3.5 T | C8: =SUM(D8:I8) | D8: =SUM(C44) | E8: =SUM(C76) | F8: =SUM(C108) | G8: =SUM(C140) | H8: =SUM(C172) | I8: =SUM(C204) | J8: 0.63 | K8: =SUM(C8*J8) | W8: 0.75 | X8: =SUM(W8-J8) | Y8: =SUM(X8*1/W8) | Z8: =SUM(C8*X8)
A9: COP 8 | B9: TRANSPORT MATERIALE MASINA 20 T | C9: =SUM(D9:I9) | D9: =SUM(C45) | E9: =SUM(C77) | F9: =SUM(C109) | G9: =SUM(C141) | H9: =SUM(C173) | I9: =SUM(C205) | J9: 1.07 | K9: =SUM(C9*J9) | W9: 1.27 | X9: =SUM(W9-J9) | Y9: =SUM(X9*1/W9) | Z9: =SUM(C9*X9)
A10: COP 9 | B10: SPARGERE BETON - CAROSABIL | C10: =SUM(D10:I10) | D10: =SUM(C46) | E10: =SUM(C78) | F10: =SUM(C110) | G10: =SUM(C142) | H10: =SUM(C174) | I10: =SUM(C206) | J10: 14.31 | K10: =SUM(C10*J10) | W10: 17.41 | X10: =SUM(W10-J10) | Y10: =SUM(X10*1/W10) | Z10: =SUM(C10*X10)
A11: COP 10 | B11: SPARGERE BETON - FUNDATIE DRUM | C11: =SUM(D11:I11) | D11: =SUM(C47) | E11: =SUM(C79) | F11: =SUM(C111) | G11: =SUM(C143) | H11: =SUM(C175) | I11: =SUM(C207) | J11: 12.45 | K11: =SUM(C11*J11) | W11: 15.55 | X11: =SUM(W11-J11) | Y11: =SUM(X11*1/W11) | Z11: =SUM(C11*X11)
A12: COP 11 | B12: DEMONTARE CABLU DIN CANALIZARE MAI MIC SAU EGAL DE 600/0.4 | C12: =SUM(D12:I12) | D12: =SUM(C48) | E12: =SUM(C80) | F12: =SUM(C112) | G12: =SUM(C144) | H12: =SUM(C176) | I12: =SUM(C208) | J12: 0.2 | K12: =SUM(C12*J12) | O12: =SUM(D12*1.25) | P12: =SUM(E12*1.25) | Q12: =SUM(F12*1.25) | R12: =SUM(G12*1.25) | S12: =SUM(H12*1.25) | T12: =SUM(I12*1.25) | W12: 0.24 | X12: =SUM(W12-J12) | Y12: =SUM(X12*1/W12) | Z12: =SUM(C12*X12)
A13: COP 12 | B13: DEMONTARE CABLU DE TELECOM DE PE ZID | C13: =SUM(D13:I13) | D13: =SUM(C49) | E13: =SUM(C81) | F13: =SUM(C113) | G13: =SUM(C145) | H13: =SUM(C177) | I13: =SUM(C209) | J13: 0.32 | K13: =SUM(C13*J13) | O13: =SUM(D13*1.3) | P13: =SUM(E13*1.3) | Q13: =SUM(F13*1.3) | R13: =SUM(G13*1.3) | S13: =SUM(H13*1.3) | T13: =SUM(I13*1.3) | W13: 0.39 | X13: =SUM(W13-J13) | Y13: =SUM(X13*1/W13) | Z13: =SUM(C13*X13)
A14: COP 13 | B14: DEMONTARE CABLU DE TELECOM. DE PE STALPI (MANOPERA DE DEMONTARE) | C14: =SUM(D14:I14) | D14: =SUM(C50) | E14: =SUM(C82) | F14: =SUM(C114) | G14: =SUM(C146) | H14: =SUM(C178) | I14: =SUM(C210) | J14: 0.15 | K14: =SUM(C14*J14) | O14: =SUM(D14) | P14: =SUM(E14) | Q14: =SUM(F14) | R14: =SUM(G14) | S14: =SUM(H14) | T14: =SUM(I14) | W14: 0.18 | X14: =SUM(W14-J14) | Y14: =SUM(X14*1/W14) | Z14: =SUM(C14*X14)
A15: COP 14 | B15: DEMONTARE STREANG SAU BRIDA SAU SARMA RADIOFICARE | C15: =SUM(D15:I15) | D15: =SUM(C51) | E15: =SUM(C83) | F15: =SUM(C115) | G15: =SUM(C147) | H15: =SUM(C179) | I15: =SUM(C211) | J15: 0.14 | K15: =SUM(C15*J15) | O15: =SUM(D15) | P15: =SUM(E15) | Q15: =SUM(F15) | R15: =SUM(G15) | S15: =SUM(H15) | T15: =SUM(I15) | W15: 0.17 | X15: =SUM(W15-J15) | Y15: =SUM(X15*1/W15) | Z15: =SUM(C15*X15)
A16: COP 15 | B16: DEMONTARE STALP DE LEMN OROC | C16: =SUM(D16:I16) | D16: =SUM(C52) | E16: =SUM(C84) | F16: =SUM(C116) | G16: =SUM(C148) | H16: =SUM(C180) | I16: =SUM(C212) | J16: 14.16 | K16: =SUM(C16*J16) | W16: 16.82 | X16: =SUM(W16-J16) | Y16: =SUM(X16*1/W16) | Z16: =SUM(C16*X16)
A17: COP 16 | B17: DEMONTARE TRAVERSA (SUPORTI RADIOFICARE) CONSOLA | C17: =SUM(D17:I17) | D17: =SUM(C53) | E17: =SUM(C85) | F17: =SUM(C117) | G17: =SUM(C149) | H17: =SUM(C181) | I17: =SUM(C213) | J17: 0.49 | K17: =SUM(C17*J17) | W17: 0.59 | X17: =SUM(W17-J17) | Y17: =SUM(X17*1/W17) | Z17: =SUM(C17*X17)
A18: COP 17 | B18: DEMONTARE CUTIE TERMINALA | C18: =SUM(D18:I18) | D18: =SUM(C54) | E18: =SUM(C86) | F18: =SUM(C118) | G18: =SUM(C150) | H18: =SUM(C182) | I18: =SUM(C214) | J18: 1.49 | K18: =SUM(C18*J18) | W18: 1.78 | X18: =SUM(W18-J18) | Y18: =SUM(X18*1/W18) | Z18: =SUM(C18*X18)
A19: COP 18 | B19: DEMONTARE APARATOARE 'U' DE CABLU (50MM) | C19: =SUM(D19:I19) | D19: =SUM(C55) | E19: =SUM(C87) | F19: =SUM(C119) | G19: =SUM(C151) | H19: =SUM(C183) | I19: =SUM(C215) | J19: 1.3 | K19: =SUM(C19*J19) | W19: 1.55 | X19: =SUM(W19-J19) | Y19: =SUM(X19*1/W19) | Z19: =SUM(C19*X19)
A20: COP 20 | B20: DEMONTARE CABLU DIN CANALIZARE MAI MARE SAU EGAL DE 600/0.6 | C20: =SUM(D20:I20) | D20: =SUM(C56) | E20: =SUM(C88) | F20: =SUM(C120) | G20: =SUM(C152) | H20: =SUM(C184) | I20: =SUM(C216) | J20: 0.51 | K20: =SUM(C20*J20) | O20: =SUM(D20*2) | P20: =SUM(E20*2) | Q20: =SUM(F20*2) | R20: =SUM(G20*2) | S20: =SUM(H20*2) | T20: =SUM(I20*2) | W20: 0.61 | X20: =SUM(W20-J20) | Y20: =SUM(X20*1/W20) | Z20: =SUM(C20*X20)
A21: COP 21 | B21: Vidanjare camine | C21: =SUM(D21:I21) | D21: =SUM(C57) | E21: =SUM(C89) | F21: =SUM(C121) | G21: =SUM(C153) | H21: =SUM(C185) | I21: =SUM(C217) | J21: 6.62 | K21: =SUM(C21*J21) | W21: 7.87 | X21: =SUM(W21-J21) | Y21: =SUM(X21*1/W21) | Z21: =SUM(C21*X21)
A22: COP 23 | B22: Asistenta Tehnica (echipa 2 tehnicieni) | C22: =SUM(D22:I22) | D22: =SUM(C58) | E22: =SUM(C90) | F22: =SUM(C122) | G22: =SUM(C154) | H22: =SUM(C186) | I22: =SUM(C218) | J22: 32 | K22: =SUM(C22*J22) | W22: 38 | X22: =SUM(W22-J22) | Y22: =SUM(X22*1/W22) | Z22: =SUM(C22*X22)
A23: COP 24 | B23: INCHIRIERE BULDOEXCAVATOR SAU UTILAJ | C23: =SUM(D23:I23) | D23: =SUM(C59) | E23: =SUM(C91) | F23: =SUM(C123) | G23: =SUM(C155) | H23: =SUM(C187) | I23: =SUM(C219) | J23: 31.31 | K23: =SUM(C23*J23) | W23: 37.18 | X23: =SUM(W23-J23) | Y23: =SUM(X23*1/W23) | Z23: =SUM(C23*X23)
A24: COP 26 | B24: Inchiriere TIR cu ora ( pentru perioada de stationare pana la incarcarea completa) | C24: =SUM(D24:I24) | D24: =SUM(C60) | E24: =SUM(C92) | F24: =SUM(C124) | G24: =SUM(C156) | H24: =SUM(C188) | I24: =SUM(C220) | J24: 13.87 | K24: =SUM(C24*J24) | N24: AERIAN : RURAL | W24: 16.47 | X24: =SUM(W24-J24) | Y24: =SUM(X24*1/W24) | Z24: =SUM(C24*X24)
A25: COP 27 | B25: DEMONTARE CABLU + STREANG | C25: =SUM(D25:I25) | D25: =SUM(C61) | E25: =SUM(C93) | F25: =SUM(C125) | G25: =SUM(C157) | H25: =SUM(C189) | I25: =SUM(C221) | J25: 0.19 | K25: =SUM(C25*J25) | N25: CANALIZATIE : URBAN | O25: =SUM(D25*1.2) | P25: =SUM(E25*1.2) | Q25: =SUM(F25*1.2) | R25: =SUM(G25*1.2) | S25: =SUM(H25*1.2) | T25: =SUM(I25*1.2) | W25: 0.23 | X25: =SUM(W25-J25) | Y25: =SUM(X25*1/W25) | Z25: =SUM(C25*X25)
A26: COP 28 | B26: DEMONTARE CABLU + BRIDA SAU STREANG + BRIDA | C26: =SUM(D26:I26) | D26: =SUM(C62) | E26: =SUM(C94) | F26: =SUM(C126) | G26: =SUM(C158) | H26: =SUM(C190) | I26: =SUM(C222) | J26: 0.16 | K26: =SUM(C26*J26) | M26: Zile lucrate | N26: 5 | O26: =SUM(D26*1.1) | P26: =SUM(E26*1.1) | Q26: =SUM(F26*1.1) | R26: =SUM(G26*1.1) | S26: =SUM(H26*1.1) | T26: =SUM(I26*1.1) | W26: 0.2 | X26: =SUM(W26-J26) | Y26: =SUM(X26*1/W26) | Z26: =SUM(C26*X26)
A27: COP 29 | B27: DEMONTARE CABLU + STREANG + BRIDA | C27: =SUM(D27:I27) | D27: =SUM(C63) | E27: =SUM(C95) | F27: =SUM(C127) | G27: =SUM(C159) | H27: =SUM(C191) | I27: =SUM(C223) | J27: 0.28 | K27: =SUM(C27*J27) | M27: Persoane Media saptamanala | N27: =SUM((D66+D98+D130+D162+D194)/N26) | O27: =SUM(D27*2) | P27: =SUM(E27*2) | Q27: =SUM(F27*2) | R27: =SUM(G27*2) | S27: =SUM(H27*2) | T27: =SUM(I27*2) | W27: 0.34 | X27: =SUM(W27-J27) | Y27: =SUM(X27*1/W27) | Z27: =SUM(C27*X27)
J28: TOTAL EURO | K28: =SUM(K3:K27) | O28: =SUM(O3:O27) | P28: =SUM(P3:P27) | Q28: =SUM(Q3:Q27) | R28: =SUM(R3:R27) | S28: =SUM(S3:S27) | T28: =SUM(T3:T27) | W28: TOTAL ADAOS | Z28: =SUM(Z3:Z27)
J29: CURS EURO | K29: 5.2 | N29: TOTAL ml / pers. | O29: =SUM(O28/D66) | P29: =SUM(P28/D98) | Q29: =SUM(Q28/D130) | R29: =SUM(R28/D162) | S29: =SUM(S28/D194) | T29: =SUM(T28/D226)
J30: TOTAL RON | K30: =SUM(K29*K28)
J31: TVA | K31: =SUM(K30*0.21) | N31: Media zil. sapt. / pers. | O31: =SUM(O29+P29+Q29+R29+S29+T29)/ N26
J32: TOTAL GENERAL | K32: =SUM(K30*1.21)
N34: Observatii :
B37: LUNI | C37: =SUM(D2)
A39: COP 1 | B39: EPUIZAREA MECANICA A APEI CU MOTOPOMPA | C39: =SUM(D39:X39)
A40: COP 2 | B40: REFACERI PAVAJE LA STRAZI (TOATTE MATERIALELE, TRANSPORTURILE SI MANOPERA INCLUSE) | C40: =SUM(D40:X40)
A41: COP 3 | B41: REFACERI PAVAJE TROTUAR, ALEI PIETONALE (TOATE MATERIALELE, TRANSPORTURILE Sl MANOPERA INCLUSE) | C41: =SUM(D41:X41)
A42: COP 4 | B42: INCHIRIERE MACARA / NACELA | C42: =SUM(D42:X42)
A43: COP 5 | B43: TRANSPORT MATERIALE MASINA 1.5 T | C43: =SUM(D43:X43)
A44: COP 6 | B44: TRANSPORT MATERIALE MASINA 3.5 T | C44: =SUM(D44:X44)
A45: COP 8 | B45: TRANSPORT MATERIALE MASINA 20 T | C45: =SUM(D45:X45)
...

Sheet SITUATIA GENERALA
T1: MARTI | AS1: VINERI
C2: SITUATIA DE LUCRARI IN SAPTAMANA | D2: =SUM(K2) | E2: - | F2: =SUM(BB2) | J2: SITUATIA | K2: 46209 | L2: 46209 | M2: 46209 | N2: 46209 | O2: 46209 | P2: 46209 | Q2: 46209 | R2: 46209 | S2: 46210 | T2: 46210 | U2: 46210 | V2: 46210 | W2: 46210 | X2: 46210 | Y2: 46210 | Z2: 46210 | AA2: 46211 | AB2: 46211 | AC2: 46211 | AD2: 46211 | AE2: 46211 | AF2: 46211 | AG2: 46211 | AH2: 46211 | AI2: 46212 | AJ2: 46212 | AK2: 46212 | AL2: 46212 | AM2: 46212 | AN2: 46212 | AO2: 46212 | AP2: 46212 | AQ2: 46212 | AR2: 46212 | AS2: 46212 | AT2: 46212 | AU2: 46212 | AV2: 46212 | AW2: 46212 | AX2: 46212 | AY2: 46214 | AZ2: 46214 | BA2: 46214 | BB2: 46214 | BC2: 46214 | BD2: 46214 | BE2: 46214 | BF2: 46214
B3: Nr. Crt | C3: Descriere articol | D3: TOTAL | E3: PRET | F3: TOTAL | G3: PO | H3: Difer. ml | I3: Difer. Pret | J3: TIRURI | K3: 1.GR | L3: 3. TL | M3: 6.PH | N3: 7.GJ | O3: 8. BZ | P3: 9. AB | Q3: 10.HR | R3: 13. BT | S3: 1.GR | T3: 3. TL | U3: 6.PH | V3: 7.GJ | W3: 8. BZ | X3: 9. AB | Y3: 10.HR | Z3: 13. BT | AA3: 1.GR | AB3: 3. TL | AC3: 6.PH | AD3: 7.GJ | AE3: 8. BZ | AF3: 9. AB | AG3: 10.HR | AH3: 13. BT | AI3: 1.GR | AJ3: 3. TL | AK3: 6.PH | AL3: 7.GJ | AM3: 8. BZ | AN3: 9. AB | AO3: 10.HR | AP3: 13. BT | AQ3: 1.GR | AR3: 3. TL | AS3: 6.PH | AT3: 7.GJ | AU3: 8. BZ | AV3: 9. AB | AW3: 10.HR | AX3: 13. BT | AY3: 1.GR | AZ3: 3. TL | BA3: 6.PH | BB3: 7.GJ | BC3: 8. BZ | BD3: 9. AB | BE3: 10.HR | BF3: 13. BT
B4: COP 1 | C4: EPUIZAREA MECANICA A APEI CU MOTOPOMPA | D4: =SUM(F4*E4) | E4: 2.465 | F4: =SUM(J4:BF4) | G4: 0 | H4: =SUM(G4-F4) | I4: =SUM(H4*E4) | J4: =SUM(SHEET_NEFOLOSIT!C6) | K4: =SUM(SHEET_GOL_5!D3+SHEET_GOL_11!D3) | L4: =SUM(SHEET_GOL_2!D3+SHEET_GOL_1!D3) | M4: =SUM(SHEET_GOL_4!D3) | N4: =SUM(SHEET_GOL_6!D3) | O4: =SUM(SHEET_GOL_12!D3+SHEET_GOL_8!D3) | P4: =SUM(SHEET_GOL_7!D3) | Q4: =SUM(SHEET_GOL_3!D3) | R4: =SUM(SHEET_GOL_9!D3+SHEET_GOL_10!D3) | S4: =SUM(SHEET_GOL_5!E3+SHEET_GOL_11!E3) | T4: =SUM(SHEET_GOL_2!E3+SHEET_GOL_1!E3) | U4: =SUM(SHEET_GOL_4!E3) | V4: =SUM(SHEET_GOL_6!E3) | W4: =SUM(SHEET_GOL_12!E3+SHEET_GOL_8!E3) | X4: =SUM(SHEET_GOL_7!E3) | Y4: =SUM(SHEET_GOL_3!E3) | Z4: =SUM(SHEET_GOL_9!E3+SHEET_GOL_10!E3) | AA4: =SUM(SHEET_GOL_5!F3+SHEET_GOL_11!F3) | AB4: =SUM(SHEET_GOL_2!F3+SHEET_GOL_1!F3) | AC4: =SUM(SHEET_GOL_4!F3) | AD4: =SUM(SHEET_GOL_6!F3) | AE4: =SUM(SHEET_GOL_12!F3+SHEET_GOL_8!F3) | AF4: =SUM(SHEET_GOL_7!F3) | AG4: =SUM(SHEET_GOL_3!F3) | AH4: =SUM(SHEET_GOL_9!F3+SHEET_GOL_10!F3) | AI4: =SUM(SHEET_GOL_5!G3+SHEET_GOL_11!G3) | AJ4: =SUM(SHEET_GOL_2!G3+SHEET_GOL_1!G3) | AK4: =SUM(SHEET_GOL_4!G3) | AL4: =SUM(SHEET_GOL_6!G3) | AM4: =SUM(SHEET_GOL_12!G3+SHEET_GOL_8!G3) | AN4: =SUM(SHEET_GOL_7!G3) | AO4: =SUM(SHEET_GOL_3!G3) | AP4: =SUM(SHEET_GOL_9!G3+SHEET_GOL_10!G3) | AQ4: =SUM(SHEET_GOL_5!H3+SHEET_GOL_11!H3) | AR4: =SUM(SHEET_GOL_2!H3+SHEET_GOL_1!H3) | AS4: =SUM(SHEET_GOL_4!H3) | AT4: =SUM(SHEET_GOL_6!H3) | AU4: =SUM(SHEET_GOL_12!H3+SHEET_GOL_8!H3) | AV4: =SUM(SHEET_GOL_7!H3) | AW4: =SUM(SHEET_GOL_3!H3) | AX4: =SUM(SHEET_GOL_9!H3+SHEET_GOL_10!H3) | AY4: =SUM(SHEET_GOL_5!I3+SHEET_GOL_11!I3) | AZ4: =SUM(SHEET_GOL_2!I3+SHEET_GOL_1!I3) | BA4: =SUM(SHEET_GOL_4!I3) | BB4: =SUM(SHEET_GOL_6!I3) | BC4: =SUM(SHEET_GOL_12!I3+SHEET_GOL_8!I3) | BD4: =SUM(SHEET_GOL_7!I3) | BE4: =SUM(SHEET_GOL_3!I3) | BF4: =SUM(SHEET_GOL_9!I3+SHEET_GOL_10!I3)
B5: COP 2 | C5: REFACERI PAVAJE LA STRAZI (TOATTE MATERIALELE, TRANSPORTURILE SI MANOPERA INCLUSE) | D5: =SUM(F5*E5) | E5: 49.53 | F5: =SUM(J5:BF5) | G5: 0 | H5: =SUM(G5-F5) | I5: =SUM(H5*E5) | J5: =SUM(SHEET_NEFOLOSIT!C7) | K5: =SUM(SHEET_GOL_5!D4+SHEET_GOL_11!D4) | L5: =SUM(SHEET_GOL_2!D4+SHEET_GOL_1!D4) | M5: =SUM(SHEET_GOL_4!D4) | N5: =SUM(SHEET_GOL_6!D4) | O5: =SUM(SHEET_GOL_12!D4+SHEET_GOL_8!D4) | P5: =SUM(SHEET_GOL_7!D4) | Q5: =SUM(SHEET_GOL_3!D4) | R5: =SUM(SHEET_GOL_9!D4+SHEET_GOL_10!D4) | S5: =SUM(SHEET_GOL_5!E4+SHEET_GOL_11!E4) | T5: =SUM(SHEET_GOL_2!E4+SHEET_GOL_1!E4) | U5: =SUM(SHEET_GOL_4!E4) | V5: =SUM(SHEET_GOL_6!E4) | W5: =SUM(SHEET_GOL_12!E4+SHEET_GOL_8!E4) | X5: =SUM(SHEET_GOL_7!E4) | Y5: =SUM(SHEET_GOL_3!E4) | Z5: =SUM(SHEET_GOL_9!E4+SHEET_GOL_10!E4) | AA5: =SUM(SHEET_GOL_5!F4+SHEET_GOL_11!F4) | AB5: =SUM(SHEET_GOL_2!F4+SHEET_GOL_1!F4) | AC5: =SUM(SHEET_GOL_4!F4) | AD5: =SUM(SHEET_GOL_6!F4) | AE5: =SUM(SHEET_GOL_12!F4+SHEET_GOL_8!F4) | AF5: =SUM(SHEET_GOL_7!F4) | AG5: =SUM(SHEET_GOL_3!F4) | AH5: =SUM(SHEET_GOL_9!F4+SHEET_GOL_10!F4) | AI5: =SUM(SHEET_GOL_5!G4+SHEET_GOL_11!G4) | AJ5: =SUM(SHEET_GOL_2!G4+SHEET_GOL_1!G4) | AK5: =SUM(SHEET_GOL_4!G4) | AL5: =SUM(SHEET_GOL_6!G4) | AM5: =SUM(SHEET_GOL_12!G4+SHEET_GOL_8!G4) | AN5: =SUM(SHEET_GOL_7!G4) | AO5: =SUM(SHEET_GOL_3!G4) | AP5: =SUM(SHEET_GOL_9!G4+SHEET_GOL_10!G4) | AQ5: =SUM(SHEET_GOL_5!H4+SHEET_GOL_11!H4) | AR5: =SUM(SHEET_GOL_2!H4+SHEET_GOL_1!H4) | AS5: =SUM(SHEET_GOL_4!H4) | AT5: =SUM(SHEET_GOL_6!H4) | AU5: =SUM(SHEET_GOL_12!H4+SHEET_GOL_8!H4) | AV5: =SUM(SHEET_GOL_7!H4) | AW5: =SUM(SHEET_GOL_3!H4) | AX5: =SUM(SHEET_GOL_9!H4+SHEET_GOL_10!H4) | AY5: =SUM(SHEET_GOL_5!I4+SHEET_GOL_11!I4) | AZ5: =SUM(SHEET_GOL_2!I4+SHEET_GOL_1!I4) | BA5: =SUM(SHEET_GOL_4!I4) | BB5: =SUM(SHEET_GOL_6!I4) | BC5: =SUM(SHEET_GOL_12!I4+SHEET_GOL_8!I4) | BD5: =SUM(SHEET_GOL_7!I4) | BE5: =SUM(SHEET_GOL_3!I4) | BF5: =SUM(SHEET_GOL_9!I4+SHEET_GOL_10!I4)
B6: COP 3 | C6: REFACERI PAVAJE TROTUAR, ALEI PIETONALE (TOATE MATERIALELE, TRANSPORTURILE Sl MANOPERA INCLUSE) | D6: =SUM(F6*E6) | E6: 21.671 | F6: =SUM(J6:BF6) | G6: 0 | H6: =SUM(G6-F6) | I6: =SUM(H6*E6) | J6: =SUM(SHEET_NEFOLOSIT!C8) | K6: =SUM(SHEET_GOL_5!D5+SHEET_GOL_11!D5) | L6: =SUM(SHEET_GOL_2!D5+SHEET_GOL_1!D5) | M6: =SUM(SHEET_GOL_4!D5) | N6: =SUM(SHEET_GOL_6!D5) | O6: =SUM(SHEET_GOL_12!D5+SHEET_GOL_8!D5) | P6: =SUM(SHEET_GOL_7!D5) | Q6: =SUM(SHEET_GOL_3!D5) | R6: =SUM(SHEET_GOL_9!D5+SHEET_GOL_10!D5) | S6: =SUM(SHEET_GOL_5!E5+SHEET_GOL_11!E5) | T6: =SUM(SHEET_GOL_2!E5+SHEET_GOL_1!E5) | U6: =SUM(SHEET_GOL_4!E5) | V6: =SUM(SHEET_GOL_6!E5) | W6: =SUM(SHEET_GOL_12!E5+SHEET_GOL_8!E5) | X6: =SUM(SHEET_GOL_7!E5) | Y6: =SUM(SHEET_GOL_3!E5) | Z6: =SUM(SHEET_GOL_9!E5+SHEET_GOL_10!E5) | AA6: =SUM(SHEET_GOL_5!F5+SHEET_GOL_11!F5) | AB6: =SUM(SHEET_GOL_2!F5+SHEET_GOL_1!F5) | AC6: =SUM(SHEET_GOL_4!F5) | AD6: =SUM(SHEET_GOL_6!F5) | AE6: =SUM(SHEET_GOL_12!F5+SHEET_GOL_8!F5) | AF6: =SUM(SHEET_GOL_7!F5) | AG6: =SUM(SHEET_GOL_3!F5) | AH6: =SUM(SHEET_GOL_9!F5+SHEET_GOL_10!F5) | AI6: =SUM(SHEET_GOL_5!G5+SHEET_GOL_11!G5) | AJ6: =SUM(SHEET_GOL_2!G5+SHEET_GOL_1!G5) | AK6: =SUM(SHEET_GOL_4!G5) | AL6: =SUM(SHEET_GOL_6!G5) | AM6: =SUM(SHEET_GOL_12!G5+SHEET_GOL_8!G5) | AN6: =SUM(SHEET_GOL_7!G5) | AO6: =SUM(SHEET_GOL_3!G5) | AP6: =SUM(SHEET_GOL_9!G5+SHEET_GOL_10!G5) | AQ6: =SUM(SHEET_GOL_5!H5+SHEET_GOL_11!H5) | AR6: =SUM(SHEET_GOL_2!H5+SHEET_GOL_1!H5) | AS6: =SUM(SHEET_GOL_4!H5) | AT6: =SUM(SHEET_GOL_6!H5) | AU6: =SUM(SHEET_GOL_12!H5+SHEET_GOL_8!H5) | AV6: =SUM(SHEET_GOL_7!H5) | AW6: =SUM(SHEET_GOL_3!H5) | AX6: =SUM(SHEET_GOL_9!H5+SHEET_GOL_10!H5) | AY6: =SUM(SHEET_GOL_5!I5+SHEET_GOL_11!I5) | AZ6: =SUM(SHEET_GOL_2!I5+SHEET_GOL_1!I5) | BA6: =SUM(SHEET_GOL_4!I5) | BB6: =SUM(SHEET_GOL_6!I5) | BC6: =SUM(SHEET_GOL_12!I5+SHEET_GOL_8!I5) | BD6: =SUM(SHEET_GOL_7!I5) | BE6: =SUM(SHEET_GOL_3!I5) | BF6: =SUM(SHEET_GOL_9!I5+SHEET_GOL_10!I5)
B7: COP 4 | C7: INCHIRIERE MACARA / NACELA | D7: =SUM(F7*E7) | E7: 31.581 | F7: =SUM(J7:BF7) | G7: 0 | H7: =SUM(G7-F7) | I7: =SUM(H7*E7) | J7: =SUM(SHEET_NEFOLOSIT!C9) | K7: =SUM(SHEET_GOL_5!D6+SHEET_GOL_11!D6) | L7: =SUM(SHEET_GOL_2!D6+SHEET_GOL_1!D6) | M7: =SUM(SHEET_GOL_4!D6) | N7: =SUM(SHEET_GOL_6!D6) | O7: =SUM(SHEET_GOL_12!D6+SHEET_GOL_8!D6) | P7: =SUM(SHEET_GOL_7!D6) | Q7: =SUM(SHEET_GOL_3!D6) | R7: =SUM(SHEET_GOL_9!D6+SHEET_GOL_10!D6) | S7: =SUM(SHEET_GOL_5!E6+SHEET_GOL_11!E6) | T7: =SUM(SHEET_GOL_2!E6+SHEET_GOL_1!E6) | U7: =SUM(SHEET_GOL_4!E6) | V7: =SUM(SHEET_GOL_6!E6) | W7: =SUM(SHEET_GOL_12!E6+SHEET_GOL_8!E6) | X7: =SUM(SHEET_GOL_7!E6) | Y7: =SUM(SHEET_GOL_3!E6) | Z7: =SUM(SHEET_GOL_9!E6+SHEET_GOL_10!E6) | AA7: =SUM(SHEET_GOL_5!F6+SHEET_GOL_11!F6) | AB7: =SUM(SHEET_GOL_2!F6+SHEET_GOL_1!F6) | AC7: =SUM(SHEET_GOL_4!F6) | AD7: =SUM(SHEET_GOL_6!F6) | AE7: =SUM(SHEET_GOL_12!F6+SHEET_GOL_8!F6) | AF7: =SUM(SHEET_GOL_7!F6) | AG7: =SUM(SHEET_GOL_3!F6) | AH7: =SUM(SHEET_GOL_9!F6+SHEET_GOL_10!F6) | AI7: =SUM(SHEET_GOL_5!G6+SHEET_GOL_11!G6) | AJ7: =SUM(SHEET_GOL_2!G6+SHEET_GOL_1!G6) | AK7: =SUM(SHEET_GOL_4!G6) | AL7: =SUM(SHEET_GOL_6!G6) | AM7: =SUM(SHEET_GOL_12!G6+SHEET_GOL_8!G6) | AN7: =SUM(SHEET_GOL_7!G6) | AO7: =SUM(SHEET_GOL_3!G6) | AP7: =SUM(SHEET_GOL_9!G6+SHEET_GOL_10!G6) | AQ7: =SUM(SHEET_GOL_5!H6+SHEET_GOL_11!H6) | AR7: =SUM(SHEET_GOL_2!H6+SHEET_GOL_1!H6) | AS7: =SUM(SHEET_GOL_4!H6) | AT7: =SUM(SHEET_GOL_6!H6) | AU7: =SUM(SHEET_GOL_12!H6+SHEET_GOL_8!H6) | AV7: =SUM(SHEET_GOL_7!H6) | AW7: =SUM(SHEET_GOL_3!H6) | AX7: =SUM(SHEET_GOL_9!H6+SHEET_GOL_10!H6) | AY7: =SUM(SHEET_GOL_5!I6+SHEET_GOL_11!I6) | AZ7: =SUM(SHEET_GOL_2!I6+SHEET_GOL_1!I6) | BA7: =SUM(SHEET_GOL_4!I6) | BB7: =SUM(SHEET_GOL_6!I6) | BC7: =SUM(SHEET_GOL_12!I6+SHEET_GOL_8!I6) | BD7: =SUM(SHEET_GOL_7!I6) | BE7: =SUM(SHEET_GOL_3!I6) | BF7: =SUM(SHEET_GOL_9!I6+SHEET_GOL_10!I6)
B8: COP 5 | C8: TRANSPORT MATERIALE MASINA 1.5 T | D8: =SUM(F8*E8) | E8: 0.614 | F8: =SUM(J8:BF8) | G8: 0 | H8: =SUM(G8-F8) | I8: =SUM(H8*E8) | J8: =SUM(SHEET_NEFOLOSIT!C10) | K8: =SUM(SHEET_GOL_5!D7+SHEET_GOL_11!D7) | L8: =SUM(SHEET_GOL_2!D7+SHEET_GOL_1!D7) | M8: =SUM(SHEET_GOL_4!D7) | N8: =SUM(SHEET_GOL_6!D7) | O8: =SUM(SHEET_GOL_12!D7+SHEET_GOL_8!D7) | P8: =SUM(SHEET_GOL_7!D7) | Q8: =SUM(SHEET_GOL_3!D7) | R8: =SUM(SHEET_GOL_9!D7+SHEET_GOL_10!D7) | S8: =SUM(SHEET_GOL_5!E7+SHEET_GOL_11!E7) | T8: =SUM(SHEET_GOL_2!E7+SHEET_GOL_1!E7) | U8: =SUM(SHEET_GOL_4!E7) | V8: =SUM(SHEET_GOL_6!E7) | W8: =SUM(SHEET_GOL_12!E7+SHEET_GOL_8!E7) | X8: =SUM(SHEET_GOL_7!E7) | Y8: =SUM(SHEET_GOL_3!E7) | Z8: =SUM(SHEET_GOL_9!E7+SHEET_GOL_10!E7) | AA8: =SUM(SHEET_GOL_5!F7+SHEET_GOL_11!F7) | AB8: =SUM(SHEET_GOL_2!F7+SHEET_GOL_1!F7) | AC8: =SUM(SHEET_GOL_4!F7) | AD8: =SUM(SHEET_GOL_6!F7) | AE8: =SUM(SHEET_GOL_12!F7+SHEET_GOL_8!F7) | AF8: =SUM(SHEET_GOL_7!F7) | AG8: =SUM(SHEET_GOL_3!F7) | AH8: =SUM(SHEET_GOL_9!F7+SHEET_GOL_10!F7) | AI8: =SUM(SHEET_GOL_5!G7+SHEET_GOL_11!G7) | AJ8: =SUM(SHEET_GOL_2!G7+SHEET_GOL_1!G7) | AK8: =SUM(SHEET_GOL_4!G7) | AL8: =SUM(SHEET_GOL_6!G7) | AM8: =SUM(SHEET_GOL_12!G7+SHEET_GOL_8!G7) | AN8: =SUM(SHEET_GOL_7!G7) | AO8: =SUM(SHEET_GOL_3!G7) | AP8: =SUM(SHEET_GOL_9!G7+SHEET_GOL_10!G7) | AQ8: =SUM(SHEET_GOL_5!H7+SHEET_GOL_11!H7) | AR8: =SUM(SHEET_GOL_2!H7+SHEET_GOL_1!H7) | AS8: =SUM(SHEET_GOL_4!H7) | AT8: =SUM(SHEET_GOL_6!H7) | AU8: =SUM(SHEET_GOL_12!H7+SHEET_GOL_8!H7) | AV8: =SUM(SHEET_GOL_7!H7) | AW8: =SUM(SHEET_GOL_3!H7) | AX8: =SUM(SHEET_GOL_9!H7+SHEET_GOL_10!H7) | AY8: =SUM(SHEET_GOL_5!I7+SHEET_GOL_11!I7) | AZ8: =SUM(SHEET_GOL_2!I7+SHEET_GOL_1!I7) | BA8: =SUM(SHEET_GOL_4!I7) | BB8: =SUM(SHEET_GOL_6!I7) | BC8: =SUM(SHEET_GOL_12!I7+SHEET_GOL_8!I7) | BD8: =SUM(SHEET_GOL_7!I7) | BE8: =SUM(SHEET_GOL_3!I7) | BF8: =SUM(SHEET_GOL_9!I7+SHEET_GOL_10!I7)
B9: COP 6 | C9: TRANSPORT MATERIALE MASINA 3.5 T | D9: =SUM(F9*E9) | E9: 0.743 | F9: =SUM(J9:BF9) | G9: 0 | H9: =SUM(G9-F9) | I9: =SUM(H9*E9) | J9: =SUM(SHEET_NEFOLOSIT!C11) | K9: =SUM(SHEET_GOL_5!D8+SHEET_GOL_11!D8) | L9: =SUM(SHEET_GOL_2!D8+SHEET_GOL_1!D8) | M9: =SUM(SHEET_GOL_4!D8) | N9: =SUM(SHEET_GOL_6!D8) | O9: =SUM(SHEET_GOL_12!D8+SHEET_GOL_8!D8) | P9: =SUM(SHEET_GOL_7!D8) | Q9: =SUM(SHEET_GOL_3!D8) | R9: =SUM(SHEET_GOL_9!D8+SHEET_GOL_10!D8) | S9: =SUM(SHEET_GOL_5!E8+SHEET_GOL_11!E8) | T9: =SUM(SHEET_GOL_2!E8+SHEET_GOL_1!E8) | U9: =SUM(SHEET_GOL_4!E8) | V9: =SUM(SHEET_GOL_6!E8) | W9: =SUM(SHEET_GOL_12!E8+SHEET_GOL_8!E8) | X9: =SUM(SHEET_GOL_7!E8) | Y9: =SUM(SHEET_GOL_3!E8) | Z9: =SUM(SHEET_GOL_9!E8+SHEET_GOL_10!E8) | AA9: =SUM(SHEET_GOL_5!F8+SHEET_GOL_11!F8) | AB9: =SUM(SHEET_GOL_2!F8+SHEET_GOL_1!F8) | AC9: =SUM(SHEET_GOL_4!F8) | AD9: =SUM(SHEET_GOL_6!F8) | AE9: =SUM(SHEET_GOL_12!F8+SHEET_GOL_8!F8) | AF9: =SUM(SHEET_GOL_7!F8) | AG9: =SUM(SHEET_GOL_3!F8) | AH9: =SUM(SHEET_GOL_9!F8+SHEET_GOL_10!F8) | AI9: =SUM(SHEET_GOL_5!G8+SHEET_GOL_11!G8) | AJ9: =SUM(SHEET_GOL_2!G8+SHEET_GOL_1!G8) | AK9: =SUM(SHEET_GOL_4!G8) | AL9: =SUM(SHEET_GOL_6!G8) | AM9: =SUM(SHEET_GOL_12!G8+SHEET_GOL_8!G8) | AN9: =SUM(SHEET_GOL_7!G8) | AO9: =SUM(SHEET_GOL_3!G8) | AP9: =SUM(SHEET_GOL_9!G8+SHEET_GOL_10!G8) | AQ9: =SUM(SHEET_GOL_5!H8+SHEET_GOL_11!H8) | AR9: =SUM(SHEET_GOL_2!H8+SHEET_GOL_1!H8) | AS9: =SUM(SHEET_GOL_4!H8) | AT9: =SUM(SHEET_GOL_6!H8) | AU9: =SUM(SHEET_GOL_12!H8+SHEET_GOL_8!H8) | AV9: =SUM(SHEET_GOL_7!H8) | AW9: =SUM(SHEET_GOL_3!H8) | AX9: =SUM(SHEET_GOL_9!H8+SHEET_GOL_10!H8) | AY9: =SUM(SHEET_GOL_5!I8+SHEET_GOL_11!I8) | AZ9: =SUM(SHEET_GOL_2!I8+SHEET_GOL_1!I8) | BA9: =SUM(SHEET_GOL_4!I8) | BB9: =SUM(SHEET_GOL_6!I8) | BC9: =SUM(SHEET_GOL_12!I8+SHEET_GOL_8!I8) | BD9: =SUM(SHEET_GOL_7!I8) | BE9: =SUM(SHEET_GOL_3!I8) | BF9: =SUM(SHEET_GOL_9!I8+SHEET_GOL_10!I8)
B10: COP 8 | C10: TRANSPORT MATERIALE MASINA 20 T | D10: =SUM(F10*E10) | E10: 1.27 | F10: =SUM(J10:BF10) | G10: 0 | H10: =SUM(G10-F10) | I10: =SUM(H10*E10) | J10: =SUM(SHEET_NEFOLOSIT!C12) | K10: =SUM(SHEET_GOL_5!D9+SHEET_GOL_11!D9) | L10: =SUM(SHEET_GOL_2!D9+SHEET_GOL_1!D9) | M10: =SUM(SHEET_GOL_4!D9) | N10: =SUM(SHEET_GOL_6!D9) | O10: =SUM(SHEET_GOL_12!D9+SHEET_GOL_8!D9) | P10: =SUM(SHEET_GOL_7!D9) | Q10: =SUM(SHEET_GOL_3!D9) | R10: =SUM(SHEET_GOL_9!D9+SHEET_GOL_10!D9) | S10: =SUM(SHEET_GOL_5!E9+SHEET_GOL_11!E9) | T10: =SUM(SHEET_GOL_2!E9+SHEET_GOL_1!E9) | U10: =SUM(SHEET_GOL_4!E9) | V10: =SUM(SHEET_GOL_6!E9) | W10: =SUM(SHEET_GOL_12!E9+SHEET_GOL_8!E9) | X10: =SUM(SHEET_GOL_7!E9) | Y10: =SUM(SHEET_GOL_3!E9) | Z10: =SUM(SHEET_GOL_9!E9+SHEET_GOL_10!E9) | AA10: =SUM(SHEET_GOL_5!F9+SHEET_GOL_11!F9) | AB10: =SUM(SHEET_GOL_2!F9+SHEET_GOL_1!F9) | AC10: =SUM(SHEET_GOL_4!F9) | AD10: =SUM(SHEET_GOL_6!F9) | AE10: =SUM(SHEET_GOL_12!F9+SHEET_GOL_8!F9) | AF10: =SUM(SHEET_GOL_7!F9) | AG10: =SUM(SHEET_GOL_3!F9) | AH10: =SUM(SHEET_GOL_9!F9+SHEET_GOL_10!F9) | AI10: =SUM(SHEET_GOL_5!G9+SHEET_GOL_11!G9) | AJ10: =SUM(SHEET_GOL_2!G9+SHEET_GOL_1!G9) | AK10: =SUM(SHEET_GOL_4!G9) | AL10: =SUM(SHEET_GOL_6!G9) | AM10: =SUM(SHEET_GOL_12!G9+SHEET_GOL_8!G9) | AN10: =SUM(SHEET_GOL_7!G9) | AO10: =SUM(SHEET_GOL_3!G9) | AP10: =SUM(SHEET_GOL_9!G9+SHEET_GOL_10!G9) | AQ10: =SUM(SHEET_GOL_5!H9+SHEET_GOL_11!H9) | AR10: =SUM(SHEET_GOL_2!H9+SHEET_GOL_1!H9) | AS10: =SUM(SHEET_GOL_4!H9) | AT10: =SUM(SHEET_GOL_6!H9) | AU10: =SUM(SHEET_GOL_12!H9+SHEET_GOL_8!H9) | AV10: =SUM(SHEET_GOL_7!H9) | AW10: =SUM(SHEET_GOL_3!H9) | AX10: =SUM(SHEET_GOL_9!H9+SHEET_GOL_10!H9) | AY10: =SUM(SHEET_GOL_5!I9+SHEET_GOL_11!I9) | AZ10: =SUM(SHEET_GOL_2!I9+SHEET_GOL_1!I9) | BA10: =SUM(SHEET_GOL_4!I9) | BB10: =SUM(SHEET_GOL_6!I9) | BC10: =SUM(SHEET_GOL_12!I9+SHEET_GOL_8!I9) | BD10: =SUM(SHEET_GOL_7!I9) | BE10: =SUM(SHEET_GOL_3!I9) | BF10: =SUM(SHEET_GOL_9!I9+SHEET_GOL_10!I9)
B11: COP 9 | C11: SPARGERE BETON - CAROSABIL | D11: =SUM(F11*E11) | E11: 17.236 | F11: =SUM(J11:BF11) | G11: 0 | H11: =SUM(G11-F11) | I11: =SUM(H11*E11) | J11: =SUM(SHEET_NEFOLOSIT!C13) | K11: =SUM(SHEET_GOL_5!D10+SHEET_GOL_11!D10) | L11: =SUM(SHEET_GOL_2!D10+SHEET_GOL_1!D10) | M11: =SUM(SHEET_GOL_4!D10) | N11: =SUM(SHEET_GOL_6!D10) | O11: =SUM(SHEET_GOL_12!D10+SHEET_GOL_8!D10) | P11: =SUM(SHEET_GOL_7!D10) | Q11: =SUM(SHEET_GOL_3!D10) | R11: =SUM(SHEET_GOL_9!D10+SHEET_GOL_10!D10) | S11: =SUM(SHEET_GOL_5!E10+SHEET_GOL_11!E10) | T11: =SUM(SHEET_GOL_2!E10+SHEET_GOL_1!E10) | U11: =SUM(SHEET_GOL_4!E10) | V11: =SUM(SHEET_GOL_6!E10) | W11: =SUM(SHEET_GOL_12!E10+SHEET_GOL_8!E10) | X11: =SUM(SHEET_GOL_7!E10) | Y11: =SUM(SHEET_GOL_3!E10) | Z11: =SUM(SHEET_GOL_9!E10+SHEET_GOL_10!E10) | AA11: =SUM(SHEET_GOL_5!F10+SHEET_GOL_11!F10) | AB11: =SUM(SHEET_GOL_2!F10+SHEET_GOL_1!F10) | AC11: =SUM(SHEET_GOL_4!F10) | AD11: =SUM(SHEET_GOL_6!F10) | AE11: =SUM(SHEET_GOL_12!F10+SHEET_GOL_8!F10) | AF11: =SUM(SHEET_GOL_7!F10) | AG11: =SUM(SHEET_GOL_3!F10) | AH11: =SUM(SHEET_GOL_9!F10+SHEET_GOL_10!F10) | AI11: =SUM(SHEET_GOL_5!G10+SHEET_GOL_11!G10) | AJ11: =SUM(SHEET_GOL_2!G10+SHEET_GOL_1!G10) | AK11: =SUM(SHEET_GOL_4!G10) | AL11: =SUM(SHEET_GOL_6!G10) | AM11: =SUM(SHEET_GOL_12!G10+SHEET_GOL_8!G10) | AN11: =SUM(SHEET_GOL_7!G10) | AO11: =SUM(SHEET_GOL_3!G10) | AP11: =SUM(SHEET_GOL_9!G10+SHEET_GOL_10!G10) | AQ11: =SUM(SHEET_GOL_5!H10+SHEET_GOL_11!H10) | AR11: =SUM(SHEET_GOL_2!H10+SHEET_GOL_1!H10) | AS11: =SUM(SHEET_GOL_4!H10) | AT11: =SUM(SHEET_GOL_6!H10) | AU11: =SUM(SHEET_GOL_12!H10+SHEET_GOL_8!H10) | AV11: =SUM(SHEET_GOL_7!H10) | AW11: =SUM(SHEET_GOL_3!H10) | AX11: =SUM(SHEET_GOL_9!H10+SHEET_GOL_10!H10) | AY11: =SUM(SHEET_GOL_5!I10+SHEET_GOL_11!I10) | AZ11: =SUM(SHEET_GOL_2!I10+SHEET_GOL_1!I10) | BA11: =SUM(SHEET_GOL_4!I10) | BB11: =SUM(SHEET_GOL_6!I10) | BC11: =SUM(SHEET_GOL_12!I10+SHEET_GOL_8!I10) | BD11: =SUM(SHEET_GOL_7!I10) | BE11: =SUM(SHEET_GOL_3!I10) | BF11: =SUM(SHEET_GOL_9!I10+SHEET_GOL_10!I10)
B12: COP 10 | C12: SPARGERE BETON - FUNDATIE DRUM | D12: =SUM(F12*E12) | E12: 15.395 | F12: =SUM(J12:BF12) | G12: 0 | H12: =SUM(G12-F12) | I12: =SUM(H12*E12) | J12: =SUM(SHEET_NEFOLOSIT!C14) | K12: =SUM(SHEET_GOL_5!D11+SHEET_GOL_11!D11) | L12: =SUM(SHEET_GOL_2!D11+SHEET_GOL_1!D11) | M12: =SUM(SHEET_GOL_4!D11) | N12: =SUM(SHEET_GOL_6!D11) | O12: =SUM(SHEET_GOL_12!D11+SHEET_GOL_8!D11) | P12: =SUM(SHEET_GOL_7!D11) | Q12: =SUM(SHEET_GOL_3!D11) | R12: =SUM(SHEET_GOL_9!D11+SHEET_GOL_10!D11) | S12: =SUM(SHEET_GOL_5!E11+SHEET_GOL_11!E11) | T12: =SUM(SHEET_GOL_2!E11+SHEET_GOL_1!E11) | U12: =SUM(SHEET_GOL_4!E11) | V12: =SUM(SHEET_GOL_6!E11) | W12: =SUM(SHEET_GOL_12!E11+SHEET_GOL_8!E11) | X12: =SUM(SHEET_GOL_7!E11) | Y12: =SUM(SHEET_GOL_3!E11) | Z12: =SUM(SHEET_GOL_9!E11+SHEET_GOL_10!E11) | AA12: =SUM(SHEET_GOL_5!F11+SHEET_GOL_11!F11) | AB12: =SUM(SHEET_GOL_2!F11+SHEET_GOL_1!F11) | AC12: =SUM(SHEET_GOL_4!F11) | AD12: =SUM(SHEET_GOL_6!F11) | AE12: =SUM(SHEET_GOL_12!F11+SHEET_GOL_8!F11) | AF12: =SUM(SHEET_GOL_7!F11) | AG12: =SUM(SHEET_GOL_3!F11) | AH12: =SUM(SHEET_GOL_9!F11+SHEET_GOL_10!F11) | AI12: =SUM(SHEET_GOL_5!G11+SHEET_GOL_11!G11) | AJ12: =SUM(SHEET_GOL_2!G11+SHEET_GOL_1!G11) | AK12: =SUM(SHEET_GOL_4!G11) | AL12: =SUM(SHEET_GOL_6!G11) | AM12: =SUM(SHEET_GOL_12!G11+SHEET_GOL_8!G11) | AN12: =SUM(SHEET_GOL_7!G11) | AO12: =SUM(SHEET_GOL_3!G11) | AP12: =SUM(SHEET_GOL_9!G11+SHEET_GOL_10!G11) | AQ12: =SUM(SHEET_GOL_5!H11+SHEET_GOL_11!H11) | AR12: =SUM(SHEET_GOL_2!H11+SHEET_GOL_1!H11) | AS12: =SUM(SHEET_GOL_4!H11) | AT12: =SUM(SHEET_GOL_6!H11) | AU12: =SUM(SHEET_GOL_12!H11+SHEET_GOL_8!H11) | AV12: =SUM(SHEET_GOL_7!H11) | AW12: =SUM(SHEET_GOL_3!H11) | AX12: =SUM(SHEET_GOL_9!H11+SHEET_GOL_10!H11) | AY12: =SUM(SHEET_GOL_5!I11+SHEET_GOL_11!I11) | AZ12: =SUM(SHEET_GOL_2!I11+SHEET_GOL_1!I11) | BA12: =SUM(SHEET_GOL_4!I11) | BB12: =SUM(SHEET_GOL_6!I11) | BC12: =SUM(SHEET_GOL_12!I11+SHEET_GOL_8!I11) | BD12: =SUM(SHEET_GOL_7!I11) | BE12: =SUM(SHEET_GOL_3!I11) | BF12: =SUM(SHEET_GOL_9!I11+SHEET_GOL_10!I11)
B13: COP 11 | C13: DEMONTARE CABLU DE TELECOM DIN CONDUCTE (MANOPERA DE DEMONTARE) | D13: =SUM(F13*E13) | E13: 0.238 | F13: =SUM(J13:BF13) | G13: 0 | H13: =SUM(G13-F13) | I13: =SUM(H13*E13) | J13: =SUM(SHEET_NEFOLOSIT!C15) | K13: =SUM(SHEET_GOL_5!D12+SHEET_GOL_11!D12) | L13: =SUM(SHEET_GOL_2!D12+SHEET_GOL_1!D12) | M13: =SUM(SHEET_GOL_4!D12) | N13: =SUM(SHEET_GOL_6!D12) | O13: =SUM(SHEET_GOL_12!D12+SHEET_GOL_8!D12) | P13: =SUM(SHEET_GOL_7!D12) | Q13: =SUM(SHEET_GOL_3!D12) | R13: =SUM(SHEET_GOL_9!D12+SHEET_GOL_10!D12) | S13: =SUM(SHEET_GOL_5!E12+SHEET_GOL_11!E12) | T13: =SUM(SHEET_GOL_2!E12+SHEET_GOL_1!E12) | U13: =SUM(SHEET_GOL_4!E12) | V13: =SUM(SHEET_GOL_6!E12) | W13: =SUM(SHEET_GOL_12!E12+SHEET_GOL_8!E12) | X13: =SUM(SHEET_GOL_7!E12) | Y13: =SUM(SHEET_GOL_3!E12) | Z13: =SUM(SHEET_GOL_9!E12+SHEET_GOL_10!E12) | AA13: =SUM(SHEET_GOL_5!F12+SHEET_GOL_11!F12) | AB13: =SUM(SHEET_GOL_2!F12+SHEET_GOL_1!F12) | AC13: =SUM(SHEET_GOL_4!F12) | AD13: =SUM(SHEET_GOL_6!F12) | AE13: =SUM(SHEET_GOL_12!F12+SHEET_GOL_8!F12) | AF13: =SUM(SHEET_GOL_7!F12) | AG13: =SUM(SHEET_GOL_3!F12) | AH13: =SUM(SHEET_GOL_9!F12+SHEET_GOL_10!F12) | AI13: =SUM(SHEET_GOL_5!G12+SHEET_GOL_11!G12) | AJ13: =SUM(SHEET_GOL_2!G12+SHEET_GOL_1!G12) | AK13: =SUM(SHEET_GOL_4!G12) | AL13: =SUM(SHEET_GOL_6!G12) | AM13: =SUM(SHEET_GOL_12!G12+SHEET_GOL_8!G12) | AN13: =SUM(SHEET_GOL_7!G12) | AO13: =SUM(SHEET_GOL_3!G12) | AP13: =SUM(SHEET_GOL_9!G12+SHEET_GOL_10!G12) | AQ13: =SUM(SHEET_GOL_5!H12+SHEET_GOL_11!H12) | AR13: =SUM(SHEET_GOL_2!H12+SHEET_GOL_1!H12) | AS13: =SUM(SHEET_GOL_4!H12) | AT13: =SUM(SHEET_GOL_6!H12) | AU13: =SUM(SHEET_GOL_12!H12+SHEET_GOL_8!H12) | AV13: =SUM(SHEET_GOL_7!H12) | AW13: =SUM(SHEET_GOL_3!H12) | AX13: =SUM(SHEET_GOL_9!H12+SHEET_GOL_10!H12) | AY13: =SUM(SHEET_GOL_5!I12+SHEET_GOL_11!I12) | AZ13: =SUM(SHEET_GOL_2!I12+SHEET_GOL_1!I12) | BA13: =SUM(SHEET_GOL_4!I12) | BB13: =SUM(SHEET_GOL_6!I12) | BC13: =SUM(SHEET_GOL_12!I12+SHEET_GOL_8!I12) | BD13: =SUM(SHEET_GOL_7!I12) | BE13: =SUM(SHEET_GOL_3!I12) | BF13: =SUM(SHEET_GOL_9!I12+SHEET_GOL_10!I12)
B14: COP 12 | C14: DEMONTARE CABLU DE TELECOM DE PE ZID | D14: =SUM(F14*E14) | E14: 0.386 | F14: =SUM(J14:BF14) | G14: 0 | H14: =SUM(G14-F14) | I14: =SUM(H14*E14) | J14: =SUM(SHEET_NEFOLOSIT!C16) | K14: =SUM(SHEET_GOL_5!D13+SHEET_GOL_11!D13) | L14: =SUM(SHEET_GOL_2!D13+SHEET_GOL_1!D13) | M14: =SUM(SHEET_GOL_4!D13) | N14: =SUM(SHEET_GOL_6!D13) | O14: =SUM(SHEET_GOL_12!D13+SHEET_GOL_8!D13) | P14: =SUM(SHEET_GOL_7!D13) | Q14: =SUM(SHEET_GOL_3!D13) | R14: =SUM(SHEET_GOL_9!D13+SHEET_GOL_10!D13) | S14: =SUM(SHEET_GOL_5!E13+SHEET_GOL_11!E13) | T14: =SUM(SHEET_GOL_2!E13+SHEET_GOL_1!E13) | U14: =SUM(SHEET_GOL_4!E13) | V14: =SUM(SHEET_GOL_6!E13) | W14: =SUM(SHEET_GOL_12!E13+SHEET_GOL_8!E13) | X14: =SUM(SHEET_GOL_7!E13) | Y14: =SUM(SHEET_GOL_3!E13) | Z14: =SUM(SHEET_GOL_9!E13+SHEET_GOL_10!E13) | AA14: =SUM(SHEET_GOL_5!F13+SHEET_GOL_11!F13) | AB14: =SUM(SHEET_GOL_2!F13+SHEET_GOL_1!F13) | AC14: =SUM(SHEET_GOL_4!F13) | AD14: =SUM(SHEET_GOL_6!F13) | AE14: =SUM(SHEET_GOL_12!F13+SHEET_GOL_8!F13) | AF14: =SUM(SHEET_GOL_7!F13) | AG14: =SUM(SHEET_GOL_3!F13) | AH14: =SUM(SHEET_GOL_9!F13+SHEET_GOL_10!F13) | AI14: =SUM(SHEET_GOL_5!G13+SHEET_GOL_11!G13) | AJ14: =SUM(SHEET_GOL_2!G13+SHEET_GOL_1!G13) | AK14: =SUM(SHEET_GOL_4!G13) | AL14: =SUM(SHEET_GOL_6!G13) | AM14: =SUM(SHEET_GOL_12!G13+SHEET_GOL_8!G13) | AN14: =SUM(SHEET_GOL_7!G13) | AO14: =SUM(SHEET_GOL_3!G13) | AP14: =SUM(SHEET_GOL_9!G13+SHEET_GOL_10!G13) | AQ14: =SUM(SHEET_GOL_5!H13+SHEET_GOL_11!H13) | AR14: =SUM(SHEET_GOL_2!H13+SHEET_GOL_1!H13) | AS14: =SUM(SHEET_GOL_4!H13) | AT14: =SUM(SHEET_GOL_6!H13) | AU14: =SUM(SHEET_GOL_12!H13+SHEET_GOL_8!H13) | AV14: =SUM(SHEET_GOL_7!H13) | AW14: =SUM(SHEET_GOL_3!H13) | AX14: =SUM(SHEET_GOL_9!H13+SHEET_GOL_10!H13) | AY14: =SUM(SHEET_GOL_5!I13+SHEET_GOL_11!I13) | AZ14: =SUM(SHEET_GOL_2!I13+SHEET_GOL_1!I13) | BA14: =SUM(SHEET_GOL_4!I13) | BB14: =SUM(SHEET_GOL_6!I13) | BC14: =SUM(SHEET_GOL_12!I13+SHEET_GOL_8!I13) | BD14: =SUM(SHEET_GOL_7!I13) | BE14: =SUM(SHEET_GOL_3!I13) | BF14: =SUM(SHEET_GOL_9!I13+SHEET_GOL_10!I13)
B15: COP 13 | C15: DEMONTARE CABLU DE TELECOM. DE PE STALPI (MANOPERA DE DEMONTARE) | D15: =SUM(F15*E15) | E15: 0.178 | F15: =SUM(J15:BF15) | G15: 0 | H15: =SUM(G15-F15) | I15: =SUM(H15*E15) | J15: =SUM(SHEET_NEFOLOSIT!C17) | K15: =SUM(SHEET_GOL_5!D14+SHEET_GOL_11!D14) | L15: =SUM(SHEET_GOL_2!D14+SHEET_GOL_1!D14) | M15: =SUM(SHEET_GOL_4!D14) | N15: =SUM(SHEET_GOL_6!D14) | O15: =SUM(SHEET_GOL_12!D14+SHEET_GOL_8!D14) | P15: =SUM(SHEET_GOL_7!D14) | Q15: =SUM(SHEET_GOL_3!D14) | R15: =SUM(SHEET_GOL_9!D14+SHEET_GOL_10!D14) | S15: =SUM(SHEET_GOL_5!E14+SHEET_GOL_11!E14) | T15: =SUM(SHEET_GOL_2!E14+SHEET_GOL_1!E14) | U15: =SUM(SHEET_GOL_4!E14) | V15: =SUM(SHEET_GOL_6!E14) | W15: =SUM(SHEET_GOL_12!E14+SHEET_GOL_8!E14) | X15: =SUM(SHEET_GOL_7!E14) | Y15: =SUM(SHEET_GOL_3!E14) | Z15: =SUM(SHEET_GOL_9!E14+SHEET_GOL_10!E14) | AA15: =SUM(SHEET_GOL_5!F14+SHEET_GOL_11!F14) | AB15: =SUM(SHEET_GOL_2!F14+SHEET_GOL_1!F14) | AC15: =SUM(SHEET_GOL_4!F14) | AD15: =SUM(SHEET_GOL_6!F14) | AE15: =SUM(SHEET_GOL_12!F14+SHEET_GOL_8!F14) | AF15: =SUM(SHEET_GOL_7!F14) | AG15: =SUM(SHEET_GOL_3!F14) | AH15: =SUM(SHEET_GOL_9!F14+SHEET_GOL_10!F14) | AI15: =SUM(SHEET_GOL_5!G14+SHEET_GOL_11!G14) | AJ15: =SUM(SHEET_GOL_2!G14+SHEET_GOL_1!G14) | AK15: =SUM(SHEET_GOL_4!G14) | AL15: =SUM(SHEET_GOL_6!G14) | AM15: =SUM(SHEET_GOL_12!G14+SHEET_GOL_8!G14) | AN15: =SUM(SHEET_GOL_7!G14) | AO15: =SUM(SHEET_GOL_3!G14) | AP15: =SUM(SHEET_GOL_9!G14+SHEET_GOL_10!G14) | AQ15: =SUM(SHEET_GOL_5!H14+SHEET_GOL_11!H14) | AR15: =SUM(SHEET_GOL_2!H14+SHEET_GOL_1!H14) | AS15: =SUM(SHEET_GOL_4!H14) | AT15: =SUM(SHEET_GOL_6!H14) | AU15: =SUM(SHEET_GOL_12!H14+SHEET_GOL_8!H14) | AV15: =SUM(SHEET_GOL_7!H14) | AW15: =SUM(SHEET_GOL_3!H14) | AX15: =SUM(SHEET_GOL_9!H14+SHEET_GOL_10!H14) | AY15: =SUM(SHEET_GOL_5!I14+SHEET_GOL_11!I14) | AZ15: =SUM(SHEET_GOL_2!I14+SHEET_GOL_1!I14) | BA15: =SUM(SHEET_GOL_4!I14) | BB15: =SUM(SHEET_GOL_6!I14) | BC15: =SUM(SHEET_GOL_12!I14+SHEET_GOL_8!I14) | BD15: =SUM(SHEET_GOL_7!I14) | BE15: =SUM(SHEET_GOL_3!I14) | BF15: =SUM(SHEET_GOL_9!I14+SHEET_GOL_10!I14)
... B28: COP 29 | C28: DEMONTARE CABLU DE TELECOM (AUTOPURTAT SAU PE CABLU OTEL-STREANG) DE PE STALPI, CABLU DE OTEL-STERANG DE PE STALPI SI CIRCUITE BRIDA INSTALATE AERIAN PE STALPI (MANOPERA DE DEMONTARE) | D28: =SUM(F28*E28) | E28: 0.337 | F28: =SUM(J28:BF28) | G28: 0 | H28: =SUM(G28-F28) | I28: =SUM(H28*E28) | J28: =SUM(SHEET_NEFOLOSIT!C30) | K28: =SUM(SHEET_GOL_5!D27+SHEET_GOL_11!D27) | L28: =SUM(SHEET_GOL_2!D27+SHEET_GOL_1!D27) | M28: =SUM(SHEET_GOL_4!D27) | N28: =SUM(SHEET_GOL_6!D27) | O28: =SUM(SHEET_GOL_12!D27+SHEET_GOL_8!D27) | P28: =SUM(SHEET_GOL_7!D27) | Q28: =SUM(SHEET_GOL_3!D27) | R28: =SUM(SHEET_GOL_9!D27+SHEET_GOL_10!D27) | S28: =SUM(SHEET_GOL_5!E27+SHEET_GOL_11!E27) | T28: =SUM(SHEET_GOL_2!E27+SHEET_GOL_1!E27) | U28: =SUM(SHEET_GOL_4!E27) | V28: =SUM(SHEET_GOL_6!E27) | W28: =SUM(SHEET_GOL_12!E27+SHEET_GOL_8!E27) | X28: =SUM(SHEET_GOL_7!E27) | Y28: =SUM(SHEET_GOL_3!E27) | Z28: =SUM(SHEET_GOL_9!E27+SHEET_GOL_10!E27) | AA28: =SUM(SHEET_GOL_5!F27+SHEET_GOL_11!F27) | AB28: =SUM(SHEET_GOL_2!F27+SHEET_GOL_1!F27) | AC28: =SUM(SHEET_GOL_4!F27) | AD28: =SUM(SHEET_GOL_6!F27) | AE28: =SUM(SHEET_GOL_12!F27+SHEET_GOL_8!F27) | AF28: =SUM(SHEET_GOL_7!F27) | AG28: =SUM(SHEET_GOL_3!F27) | AH28: =SUM(SHEET_GOL_9!F27+SHEET_GOL_10!F27) | AI28: =SUM(SHEET_GOL_5!G27+SHEET_GOL_11!G27) | AJ28: =SUM(SHEET_GOL_2!G27+SHEET_GOL_1!G27) | AK28: =SUM(SHEET_GOL_4!G27) | AL28: =SUM(SHEET_GOL_6!G27) | AM28: =SUM(SHEET_GOL_12!G27+SHEET_GOL_8!G27) | AN28: =SUM(SHEET_GOL_7!G27) | AO28: =SUM(SHEET_GOL_3!G27) | AP28: =SUM(SHEET_GOL_9!G27+SHEET_GOL_10!G27) | AQ28: =SUM(SHEET_GOL_5!H27+SHEET_GOL_11!H27) | AR28: =SUM(SHEET_GOL_2!H27+SHEET_GOL_1!H27) | AS28: =SUM(SHEET_GOL_4!H27) | AT28: =SUM(SHEET_GOL_6!H27) | AU28: =SUM(SHEET_GOL_12!H27+SHEET_GOL_8!H27) | AV28: =SUM(SHEET_GOL_7!H27) | AW28: =SUM(SHEET_GOL_3!H27) | AX28: =SUM(SHEET_GOL_9!H27+SHEET_GOL_10!H27) | AY28: =SUM(SHEET_GOL_5!I27+SHEET_GOL_11!I27) | AZ28: =SUM(SHEET_GOL_2!I27+SHEET_GOL_1!I27) | BA28: =SUM(SHEET_GOL_4!I27) | BB28: =SUM(SHEET_GOL_6!I27) | BC28: =SUM(SHEET_GOL_12!I27+SHEET_GOL_8!I27) | BD28: =SUM(SHEET_GOL_7!I27) | BE28: =SUM(SHEET_GOL_3!I27) | BF28: =SUM(SHEET_GOL_9!I27+SHEET_GOL_10!I27)
C30: TOTAL | D30: =SUM(D4:D28) | I30: =SUM(I4:I29)
E36: pret / kg | F36: total
C37: Kg - 8 situatii | D37: =SUM(SHEET_GOL_1!F227+SHEET_GOL_2!F227+#REF!+SHEET_GOL_3!F227+SHEET_GOL_4!F227+SHEET_GOL_5!F227+SHEET_GOL_6!F227+SHEET_GOL_7!F227)
C38: kg - 6 situatii | D38: =SUM(SHEET_GOL_12!F227+SHEET_GOL_8!F227+SHEET_GOL_9!F227+SHEET_GOL_10!F227+SHEET_GOL_11!F228+#REF!)
C39: TOTAL kg | D39: =SUM(D37:D38) | E39: 0.02 | F39: =SUM(D39*E39)
C42: Indexare Km ? | D42: 0 | E42: 0 | F42: 0
CH47: `
A48: 26 | AV48: `
B50: 1.GIURGIU
B51: Nr. Crt | C51: Descriere articol | D51: TOTAL | E51: 46209 | F51: 46210 | G51: 46211 | H51: 46212 | I51: 46213 | J51: 46214
B52: COP 1 | C52: EPUIZAREA MECANICA A APEI CU MOTOPOMPA | D52: =SUM(E52:J52) | E52: =SUM(K4) | F52: =SUM(S4) | G52: =SUM(AA4) | H52: =SUM(AI4) | I52: =SUM(AQ4) | J52: =SUM(AY4)
B53: COP 2 | C53: REFACERI PAVAJE LA STRAZI (TOATTE MATERIALELE, TRANSPORTURILE SI MANOPERA INCLUSE) | D53: =SUM(E53:J53) | E53: =SUM(K5) | F53: =SUM(S5) | G53: =SUM(AA5) | H53: =SUM(AI5) | I53: =SUM(AQ5) | J53: =SUM(AY5)
B54: COP 3 | C54: REFACERI PAVAJE TROTUAR, ALEI PIETONALE (TOATE MATERIALELE, TRANSPORTURILE Sl MANOPERA INCLUSE) | D54: =SUM(E54:J54) | E54: =SUM(K6) | F54: =SUM(S6) | G54: =SUM(AA6) | H54: =SUM(AI6) | I54: =SUM(AQ6) | J54: =SUM(AY6)
B55: COP 4 | C55: INCHIRIERE MACARA / NACELA | D55: =SUM(E55:J55) | E55: =SUM(K7) | F55: =SUM(S7) | G55: =SUM(AA7) | H55: =SUM(AI7) | I55: =SUM(AQ7) | J55: =SUM(AY7)
B56: COP 5 | C56: TRANSPORT MATERIALE MASINA 1.5 T | D56: =SUM(E56:J56) | E56: =SUM(K8) | F56: =SUM(S8) | G56: =SUM(AA8) | H56: =SUM(AI8) | I56: =SUM(AQ8) | J56: =SUM(AY8)
B57: COP 6 | C57: TRANSPORT MATERIALE MASINA 3.5 T | D57: =SUM(E57:J57) | E57: =SUM(K9) | F57: =SUM(S9) | G57: =SUM(AA9) | H57: =SUM(AI9) | I57: =SUM(AQ9) | J57: =SUM(AY9)
B58: COP 8 | C58: TRANSPORT MATERIALE MASINA 20 T | D58: =SUM(E58:J58) | E58: =SUM(K10) | F58: =SUM(S10) | G58: =SUM(AA10) | H58: =SUM(AI10) | I58: =SUM(AQ10) | J58: =SUM(AY10)
B59: COP 9 | C59: SPARGERE BETON - CAROSABIL | D59: =SUM(E59:J59) | E59: =SUM(K11) | F59: =SUM(S11) | G59: =SUM(AA11) | H59: =SUM(AI11) | I59: =SUM(AQ11) | J59: =SUM(AY11)
B60: COP 10 | C60: SPARGERE BETON - FUNDATIE DRUM | D60: =SUM(E60:J60) | E60: =SUM(K12) | F60: =SUM(S12) | G60: =SUM(AA12) | H60: =SUM(AI12) | I60: =SUM(AQ12) | J60: =SUM(AY12)
B61: COP 11 | C61: DEMONTARE CABLU DE TELECOM DIN CONDUCTE (MANOPERA DE DEMONTARE) | D61: =SUM(E61:J61) | E61: =SUM(K13) | F61: =SUM(S13) | G61: =SUM(AA13) | H61: =SUM(AI13) | I61: =SUM(AQ13) | J61: =SUM(AY13)
B62: COP 12 | C62: DEMONTARE CABLU DE TELECOM DE PE ZID | D62: =SUM(E62:J62) | E62: =SUM(K14) | F62: =SUM(S14) | G62: =SUM(AA14) | H62: =SUM(AI14) | I62: =SUM(AQ14) | J62: =SUM(AY14)
B63: COP 13 | C63: DEMONTARE CABLU DE TELECOM. DE PE STALPI (MANOPERA DE DEMONTARE) | D63: =SUM(E63:J63) | E63: =SUM(K15) | F63: =SUM(S15) | G63: =SUM(AA15) | H63: =SUM(AI15) | I63: =SUM(AQ15) | J63: =SUM(AY15)
... B76: COP 29 | C76: DEMONTARE CABLU DE TELECOM (AUTOPURTAT SAU PE CABLU OTEL-STREANG) DE PE STALPI, CABLU DE OTEL-STERANG DE PE STALPI SI CIRCUITE BRIDA INSTALATE AERIAN PE STALPI (MANOPERA DE DEMONTARE) | D76: =SUM(E76:J76) | E76: =SUM(K28) | F76: =SUM(S28) | G76: =SUM(AA28) | H76: =SUM(AI28) | I76: =SUM(AQ28) | J76: =SUM(AY28)
B80: 2.DOLJ
...

Sheet SHEET_NEFOLOSIT
A5: Nr. Crt | B5: Descriere articol | C5: TOTAL | D5: 46209 | E5: 46210 | F5: 46211 | G5: 46212 | H5: 46213 | I5: 46214 | J5: PRET | K5: TOTAL | N5: Nr crt | O5: Judet / Localitate | P5: Km | Q5: Ore Stationare
A6: COP 1 | B6: EPUIZAREA MECANICA A APEI CU MOTOPOMPA | C6: =SUM(D6:I6) | D6: =SUM(C37) | E6: =SUM(C65) | F6: =SUM(C93) | G6: =SUM(C121) | H6: =SUM(C149) | I6: =SUM(D178) | J6: 2.465 | K6: =SUM(C6*J6) | N6: 1 | O6: PRAHOVA / Brazi | P6: =SUM(D43+D71+D99+D127+D155) | Q6: =SUM(D58+D86+D114+D142+D170)
A7: COP 2 | B7: REFACERI PAVAJE LA STRAZI (TOATTE MATERIALELE, TRANSPORTURILE SI MANOPERA INCLUSE) | C7: =SUM(D7:I7) | D7: =SUM(C38) | E7: =SUM(C66) | F7: =SUM(C94) | G7: =SUM(C122) | H7: =SUM(C150) | I7: =SUM(D179) | J7: 49.53 | K7: =SUM(C7*J7) | N7: 2 | O7: BUZAU / Buzau | P7: =SUM(E43+E71+E99+E127+E155) | Q7: =SUM(E58+E86+E114+E142+E170+E199)
A8: COP 3 | B8: REFACERI PAVAJE TROTUAR, ALEI PIETONALE (TOATE MATERIALELE, TRANSPORTURILE Sl MANOPERA INCLUSE) | C8: =SUM(D8:I8) | D8: =SUM(C39) | E8: =SUM(C67) | F8: =SUM(C95) | G8: =SUM(C123) | H8: =SUM(C151) | I8: =SUM(D180) | J8: 21.671 | K8: =SUM(C8*J8) | N8: 3 | O8: TULCEA / Tulcea | P8: =SUM(F43+F71+F99+F127+F155) | Q8: =SUM(F58+F86+F114+F142+F170+F199)
A9: COP 4 | B9: INCHIRIERE MACARA / NACELA | C9: =SUM(D9:I9) | D9: =SUM(C40) | E9: =SUM(C68) | F9: =SUM(C96) | G9: =SUM(C124) | H9: =SUM(C152) | I9: =SUM(D181) | J9: 31.581 | K9: =SUM(C9*J9) | N9: 4 | O9: HARGHITA /Miercurea-Ciuc | P9: =SUM(G43+G71+G99+G127+G155) | Q9: =SUM(G58+G86+G114+G142+G170)
A10: COP 5 | B10: TRANSPORT MATERIALE MASINA 1.5 T | C10: =SUM(D10:I10) | D10: =SUM(C41) | E10: =SUM(C69) | F10: =SUM(C97) | G10: =SUM(C125) | H10: =SUM(C153) | I10: 0 | J10: 0.614 | K10: =SUM(C10*J10) | N10: 5 | O10: VRANCEA / Focsani | P10: =SUM(H43+H71+H99+H127+H155) | Q10: =SUM(H58+H86+H114+H142+H170+H199)
A11: COP 6 | B11: TRANSPORT MATERIALE MASINA 3.5 T | C11: =SUM(D11:I11) | D11: =SUM(C42) | E11: =SUM(C70) | F11: =SUM(C98) | G11: =SUM(C126) | H11: =SUM(C154) | I11: =SUM(D183) | J11: 0.743 | K11: =SUM(C11*J11) | N11: 6 | O11: BOTOSANI / Botosani | P11: =SUM(I43+I71+I99+I127+I155+I184) | Q11: =SUM(I58+I86+I114+I142+I170+I199)
A12: COP 8 | B12: TRANSPORT MATERIALE MASINA 20 T | C12: =SUM(D12:I12) | D12: =SUM(C43) | E12: =SUM(C71) | F12: =SUM(C99) | G12: =SUM(C127) | H12: =SUM(C155) | I12: =SUM(D184) | J12: 1.27 | K12: =SUM(C12*J12) | N12: 7 | O12: GORJ / Targu- jiu | P12: =SUM(J43+J71+J99+J127+J1550) | Q12: =SUM(J58+J86+J114+J142+J170)
A13: COP 9 | B13: SPARGERE BETON - CAROSABIL | C13: =SUM(D13:I13) | D13: =SUM(C44) | E13: =SUM(C72) | F13: =SUM(C100) | G13: =SUM(C128) | H13: =SUM(C156) | I13: =SUM(D185) | J13: 17.236 | K13: =SUM(C13*J13) | N13: 8 | O13: GIURGIU / Giurgiu | P13: =SUM(K43+K71+K99+K127+K155+K184) | Q13: =SUM(K58+K86+K114+K142+K170+K199)
A14: COP 10 | B14: SPARGERE BETON - FUNDATIE DRUM | C14: =SUM(D14:I14) | D14: =SUM(C45) | E14: =SUM(C73) | F14: =SUM(C101) | G14: =SUM(C129) | H14: =SUM(C157) | I14: =SUM(D186) | J14: 15.395 | K14: =SUM(C14*J14) | N14: 9 | P14: =SUM(L43+L71+L99+L127+L155+L184) | Q14: =SUM(L58+L86+L114+L142+L170+L199)
A15: COP 11 | B15: DEMONTARE CABLU DE TELECOM DIN CONDUCTE (MANOPERA DE DEMONTARE) | C15: =SUM(D15:I15) | D15: =SUM(C46) | E15: =SUM(C74) | F15: =SUM(C102) | G15: =SUM(C130) | H15: =SUM(C158) | I15: =SUM(D187) | J15: 0.238 | K15: =SUM(C15*J15) | N15: 10 | P15: =SUM(M43+M71+M99+M127+M155+M184) | Q15: =SUM(M58+M86+M114+M142+M170+M199)
A16: COP 12 | B16: DEMONTARE CABLU DE TELECOM DE PE ZID | C16: =SUM(D16:I16) | D16: =SUM(C47) | E16: =SUM(C75) | F16: =SUM(C103) | G16: =SUM(C131) | H16: =SUM(C159) | I16: =SUM(D188) | J16: 0.386 | K16: =SUM(C16*J16)
A17: COP 13 | B17: DEMONTARE CABLU DE TELECOM. DE PE STALPI (MANOPERA DE DEMONTARE) | C17: =SUM(D17:I17) | D17: =SUM(C48) | E17: =SUM(C76) | F17: =SUM(C104) | G17: =SUM(C132) | H17: =SUM(C160) | I17: =SUM(D189) | J17: 0.178 | K17: =SUM(C17*J17)
A18: COP 14 | B18: DEMONTARE CIRC. TC. SI CABLURI DE OTEL INST. AERIAN PE STALPI: SARMA OL ZN SAU CU | C18: =SUM(D18:I18) | D18: =SUM(C49) | E18: =SUM(C77) | F18: =SUM(C105) | G18: =SUM(C133) | H18: =SUM(C161) | I18: =SUM(D190) | J18: 0.168 | K18: =SUM(C18*J18) | N18: TOTAL | P18: =SUM(P6:P17) | Q18: =SUM(Q6:Q17)
A19: COP 15 | B19: DEMONTARE STALP DE LEMN (INCLUSIV PROPTA SI/SAU ANCORAJ) | C19: =SUM(D19:I19) | D19: =SUM(C50) | E19: =SUM(C78) | F19: =SUM(C106) | G19: =SUM(C134) | H19: =SUM(C162) | I19: =SUM(D191) | J19: 16.652 | K19: =SUM(C19*J19)
A20: COP 16 | B20: DEMONTARE TRAVERSA LEMN SI MAT. AUX. | C20: =SUM(D20:I20) | D20: =SUM(C51) | E20: =SUM(C79) | F20: =SUM(C107) | G20: =SUM(C135) | H20: =SUM(C163) | I20: =SUM(D192) | J20: 0.584 | K20: =SUM(C20*J20)
A21: COP 17 | B21: DEMONTARE CUTIE TERMINALA | C21: =SUM(D21:I21) | D21: =SUM(C52) | E21: =SUM(C80) | F21: =SUM(C108) | G21: =SUM(C136) | H21: =SUM(C164) | I21: =SUM(D193) | J21: 1.762 | K21: =SUM(C21*J21)
A22: COP 18 | B22: DEMONTARE APARATOARE 'U' DE CABLU | C22: =SUM(D22:I22) | D22: =SUM(C53) | E22: =SUM(C81) | F22: =SUM(C109) | G22: =SUM(C137) | H22: =SUM(C165) | I22: =SUM(D194) | J22: 1.535 | K22: =SUM(C22*J22)
A23: COP 20 | B23: DEMONTARE CU UTILAJ CABLU DE TELECOM DIN CONDUCTE AVAND GREUTATEA CUPRINSA INTRE 2.61-12KG/M (MANOPERA DE DEMONTARE) | C23: =SUM(D23:I23) | D23: =SUM(C54) | E23: =SUM(C82) | F23: =SUM(C110) | G23: =SUM(C138) | H23: =SUM(C166) | I23: =SUM(D195) | J23: 0.604 | K23: =SUM(C23*J23)
A24: COP 21 | B24: Vidanjare camine | C24: =SUM(D24:I24) | D24: =SUM(C55) | E24: =SUM(C83) | F24: =SUM(C111) | G24: =SUM(C139) | H24: =SUM(C167) | I24: =SUM(D196) | J24: 7.791 | K24: =SUM(C24*J24)
A25: COP 23 | B25: Asistenta Tehnica (echipa 2 tehnicieni) | C25: =SUM(D25:I25) | D25: =SUM(C56) | E25: =SUM(C84) | F25: =SUM(C112) | G25: =SUM(C140) | H25: =SUM(C168) | I25: 0 | J25: 37.62 | K25: =SUM(C25*J25)
A26: COP 24 | B26: INCHIRIERE buldozer | C26: =SUM(D26:I26) | D26: =SUM(C57) | E26: =SUM(C85) | F26: =SUM(C113) | G26: =SUM(C141) | H26: =SUM(C169) | I26: =SUM(D198) | J26: 36.808 | K26: =SUM(C26*J26)
A27: COP 26 | B27: Inchiriere TIR cu ora ( pentru perioada de stationare pana la incarcarea completa) | C27: =SUM(D27:I27) | D27: =SUM(C58) | E27: =SUM(C86) | F27: =SUM(C114) | G27: =SUM(C142) | H27: =SUM(C170) | I27: =SUM(C199) | J27: 16.305 | K27: =SUM(C27*J27)
A28: COP 27 | B28: DEMONTARE CABLU DE TELECOM DE PE STALPI SI CABLU DE OTEL INSTALAT AERIAN: SARMA OL ZN SAU CU (MANOPERA DE DEMONTARE) | C28: =SUM(D28:I28) | D28: =SUM(C59) | E28: =SUM(C87) | F28: =SUM(C115) | G28: =SUM(C143) | H28: =SUM(C171) | I28: =SUM(D200) | J28: 0.228 | K28: =SUM(C28*J28)
A29: COP 28 | B29: DEMONTARE CABLU DE TELECOM DE PE STALPI SI CIRC. BRIDA INSTALATE AERIAN PE STALPI (MANOPERA DE DEMONTARE) | C29: =SUM(D29:I29) | D29: =SUM(C60) | E29: =SUM(C88) | F29: =SUM(C116) | G29: =SUM(C144) | H29: =SUM(C172) | I29: =SUM(D201) | J29: 0.198 | K29: =SUM(C29*J29)
A30: COP 29 | B30: DEMONTARE CABLU DE TELECOM (AUTOPURTAT SAU PE CABLU OTEL-STREANG) DE PE STALPI, CABLU DE OTEL-STERANG DE PE STALPI SI CIRCUITE BRIDA INSTALATE AERIAN PE STALPI (MANOPERA DE DEMONTARE) | C30: =SUM(D30:I30) | D30: =SUM(C61) | E30: =SUM(C89) | F30: =SUM(C117) | G30: =SUM(C145) | H30: =SUM(C173) | I30: =SUM(D202) | J30: 0.337 | K30: =SUM(C30*J30)
J31: TOTAL | K31: =SUM(K6:K30)
B35: LUNI | C35: =SUM(D5)
A37: COP 1 | B37: EPUIZAREA MECANICA A APEI CU MOTOPOMPA | C37: =SUM(D37:X37)
A38: COP 2 | B38: REFACERI PAVAJE LA STRAZI (TOATTE MATERIALELE, TRANSPORTURILE SI MANOPERA INCLUSE) | C38: =SUM(D38:X38)
A39: COP 3 | B39: REFACERI PAVAJE TROTUAR, ALEI PIETONALE (TOATE MATERIALELE, TRANSPORTURILE Sl MANOPERA INCLUSE) | C39: =SUM(D39:X39)
A40: COP 4 | B40: INCHIRIERE MACARA / NACELA | C40: =SUM(D40:X40)
A41: COP 5 | B41: TRANSPORT MATERIALE MASINA 1.5 T | C41: 0
A42: COP 6 | B42: TRANSPORT MATERIALE MASINA 3.5 T | C42: =SUM(D42:X42)
A43: COP 8 | B43: TRANSPORT MATERIALE MASINA 20 T | C43: =SUM(D43:X43)
A44: COP 9 | B44: SPARGERE BETON - CAROSABIL | C44: =SUM(D44:X44)
A45: COP 10 | B45: SPARGERE BETON - FUNDATIE DRUM | C45: =SUM(D45:X45)
A46: COP 11 | B46: DEMONTARE CABLU DE TELECOM DIN CONDUCTE (MANOPERA DE DEMONTARE) | C46: =SUM(D46:X46)
A47: COP 12 | B47: DEMONTARE CABLU DE TELECOM DE PE ZID | C47: =SUM(D47:X47)
A48: COP 13 | B48: DEMONTARE CABLU DE TELECOM. DE PE STALPI (MANOPERA DE DEMONTARE) | C48: =SUM(D48:X48)
...

Sheet Popescu2- Bacau
A2: Nr. Crt | B2: Descriere articol | C2: TOTAL | D2: 46328 | E2: 46329 | F2: 46330 | G2: 46331 | H2: 46332 | I2: 46333 | J2: PRET | K2: TOTAL | W2: PRET BIS | X2: ADAOS ml | Y2: ADAOS % | Z2: ADAOS
A3: COP 1 | B3: EPUIZAREA MECANICA A APEI CU MOTOPOMPA | C3: =SUM(D3:I3) | D3: =SUM(C39) | E3: =SUM(C71) | F3: =SUM(C103) | G3: =SUM(C135) | H3: =SUM(C167) | I3: =SUM(C199) | J3: 2.09 | K3: =SUM(C3*J3) | W3: 2.49 | X3: =SUM(W3-J3) | Y3: =SUM(X3*1/W3) | Z3: =SUM(C3*X3)
A4: COP 2 | B4: REFACERI PAVAJE LA STRAZI (TOATTE MATERIALELE, TRANSPORTURILE SI MANOPERA INCLUSE) | C4: =SUM(D4:I4) | D4: =SUM(C40) | E4: =SUM(C72) | F4: =SUM(C104) | G4: =SUM(C136) | H4: =SUM(C168) | I4: =SUM(C200) | J4: 42.12 | K4: =SUM(C4*J4) | W4: 50.03 | X4: =SUM(W4-J4) | Y4: =SUM(X4*1/W4) | Z4: =SUM(C4*X4)
A5: COP 3 | B5: REFACERI PAVAJE TROTUAR, ALEI PIETONALE (TOATE MATERIALELE, TRANSPORTURILE Sl MANOPERA INCLUSE) | C5: =SUM(D5:I5) | D5: =SUM(C41) | E5: =SUM(C73) | F5: =SUM(C105) | G5: =SUM(C137) | H5: =SUM(C169) | I5: =SUM(C201) | J5: 18.43 | K5: =SUM(C5*J5) | W5: 21.89 | X5: =SUM(W5-J5) | Y5: =SUM(X5*1/W5) | Z5: =SUM(C5*X5)
A6: COP 4 | B6: INCHIRIERE MACARA / NACELA | C6: =SUM(D6:I6) | D6: =SUM(C42) | E6: =SUM(C74) | F6: =SUM(C106) | G6: =SUM(C138) | H6: =SUM(C170) | I6: =SUM(C202) | J6: 27 | K6: =SUM(C6*J6) | W6: 31.29 | X6: =SUM(W6-J6) | Y6: =SUM(X6*1/W6) | Z6: =SUM(C6*X6)
A7: COP 5 | B7: TRANSPORT MATERIALE MASINA 1.5 T | C7: =SUM(D7:I7) | D7: =SUM(C43) | E7: =SUM(C75) | F7: =SUM(C107) | G7: =SUM(C139) | H7: =SUM(C171) | I7: =SUM(C203) | J7: 0.41 | K7: =SUM(C7*J7) | W7: 0.62 | X7: =SUM(W7-J7) | Y7: =SUM(X7*1/W7) | Z7: =SUM(C7*X7)
A8: COP 6 | B8: TRANSPORT MATERIALE MASINA 3.5 T | C8: =SUM(D8:I8) | D8: =SUM(C44) | E8: =SUM(C76) | F8: =SUM(C108) | G8: =SUM(C140) | H8: =SUM(C172) | I8: =SUM(C204) | J8: 0.63 | K8: =SUM(C8*J8) | W8: 0.75 | X8: =SUM(W8-J8) | Y8: =SUM(X8*1/W8) | Z8: =SUM(C8*X8)
A9: COP 8 | B9: TRANSPORT MATERIALE MASINA 20 T | C9: =SUM(D9:I9) | D9: =SUM(C45) | E9: =SUM(C77) | F9: =SUM(C109) | G9: =SUM(C141) | H9: =SUM(C173) | I9: =SUM(C205) | J9: 1.07 | K9: =SUM(C9*J9) | W9: 1.27 | X9: =SUM(W9-J9) | Y9: =SUM(X9*1/W9) | Z9: =SUM(C9*X9)
A10: COP 9 | B10: SPARGERE BETON - CAROSABIL | C10: =SUM(D10:I10) | D10: =SUM(C46) | E10: =SUM(C78) | F10: =SUM(C110) | G10: =SUM(C142) | H10: =SUM(C174) | I10: =SUM(C206) | J10: 14.31 | K10: =SUM(C10*J10) | W10: 17.41 | X10: =SUM(W10-J10) | Y10: =SUM(X10*1/W10) | Z10: =SUM(C10*X10)
A11: COP 10 | B11: SPARGERE BETON - FUNDATIE DRUM | C11: =SUM(D11:I11) | D11: =SUM(C47) | E11: =SUM(C79) | F11: =SUM(C111) | G11: =SUM(C143) | H11: =SUM(C175) | I11: =SUM(C207) | J11: 12.45 | K11: =SUM(C11*J11) | W11: 15.55 | X11: =SUM(W11-J11) | Y11: =SUM(X11*1/W11) | Z11: =SUM(C11*X11)
A12: COP 11 | B12: DEMONTARE CABLU DIN CANALIZARE MAI MIC SAU EGAL DE 600/0.4 | C12: =SUM(D12:I12) | D12: =SUM(C48) | E12: =SUM(C80) | F12: =SUM(C112) | G12: =SUM(C144) | H12: =SUM(C176) | I12: =SUM(C208) | J12: 0.2 | K12: =SUM(C12*J12) | O12: =SUM(D12*1.25) | P12: =SUM(E12*1.25) | Q12: =SUM(F12*1.25) | R12: =SUM(G12*1.25) | S12: =SUM(H12*1.25) | T12: =SUM(I12*1.25) | W12: 0.24 | X12: =SUM(W12-J12) | Y12: =SUM(X12*1/W12) | Z12: =SUM(C12*X12)
A13: COP 12 | B13: DEMONTARE CABLU DE TELECOM DE PE ZID | C13: =SUM(D13:I13) | D13: =SUM(C49) | E13: =SUM(C81) | F13: =SUM(C113) | G13: =SUM(C145) | H13: =SUM(C177) | I13: =SUM(C209) | J13: 0.32 | K13: =SUM(C13*J13) | O13: =SUM(D13*1.3) | P13: =SUM(E13*1.3) | Q13: =SUM(F13*1.3) | R13: =SUM(G13*1.3) | S13: =SUM(H13*1.3) | T13: =SUM(I13*1.3) | W13: 0.39 | X13: =SUM(W13-J13) | Y13: =SUM(X13*1/W13) | Z13: =SUM(C13*X13)
A14: COP 13 | B14: DEMONTARE CABLU DE TELECOM. DE PE STALPI (MANOPERA DE DEMONTARE) | C14: =SUM(D14:I14) | D14: =SUM(C50) | E14: =SUM(C82) | F14: =SUM(C114) | G14: =SUM(C146) | H14: =SUM(C178) | I14: =SUM(C210) | J14: 0.15 | K14: =SUM(C14*J14) | O14: =SUM(D14) | P14: =SUM(E14) | Q14: =SUM(F14) | R14: =SUM(G14) | S14: =SUM(H14) | T14: =SUM(I14) | W14: 0.18 | X14: =SUM(W14-J14) | Y14: =SUM(X14*1/W14) | Z14: =SUM(C14*X14)
A15: COP 14 | B15: DEMONTARE STREANG SAU BRIDA SAU SARMA RADIOFICARE | C15: =SUM(D15:I15) | D15: =SUM(C51) | E15: =SUM(C83) | F15: =SUM(C115) | G15: =SUM(C147) | H15: =SUM(C179) | I15: =SUM(C211) | J15: 0.14 | K15: =SUM(C15*J15) | O15: =SUM(D15) | P15: =SUM(E15) | Q15: =SUM(F15) | R15: =SUM(G15) | S15: =SUM(H15) | T15: =SUM(I15) | W15: 0.17 | X15: =SUM(W15-J15) | Y15: =SUM(X15*1/W15) | Z15: =SUM(C15*X15)
A16: COP 15 | B16: DEMONTARE STALP DE LEMN OROC | C16: =SUM(D16:I16) | D16: =SUM(C52) | E16: =SUM(C84) | F16: =SUM(C116) | G16: =SUM(C148) | H16: =SUM(C180) | I16: =SUM(C212) | J16: 14.16 | K16: =SUM(C16*J16) | W16: 16.82 | X16: =SUM(W16-J16) | Y16: =SUM(X16*1/W16) | Z16: =SUM(C16*X16)
A17: COP 16 | B17: DEMONTARE TRAVERSA (SUPORTI RADIOFICARE) CONSOLA | C17: =SUM(D17:I17) | D17: =SUM(C53) | E17: =SUM(C85) | F17: =SUM(C117) | G17: =SUM(C149) | H17: =SUM(C181) | I17: =SUM(C213) | J17: 0.49 | K17: =SUM(C17*J17) | W17: 0.59 | X17: =SUM(W17-J17) | Y17: =SUM(X17*1/W17) | Z17: =SUM(C17*X17)
A18: COP 17 | B18: DEMONTARE CUTIE TERMINALA | C18: =SUM(D18:I18) | D18: =SUM(C54) | E18: =SUM(C86) | F18: =SUM(C118) | G18: =SUM(C150) | H18: =SUM(C182) | I18: =SUM(C214) | J18: 1.49 | K18: =SUM(C18*J18) | W18: 1.78 | X18: =SUM(W18-J18) | Y18: =SUM(X18*1/W18) | Z18: =SUM(C18*X18)
A19: COP 18 | B19: DEMONTARE APARATOARE 'U' DE CABLU (50MM) | C19: =SUM(D19:I19) | D19: =SUM(C55) | E19: =SUM(C87) | F19: =SUM(C119) | G19: =SUM(C151) | H19: =SUM(C183) | I19: =SUM(C215) | J19: 1.3 | K19: =SUM(C19*J19) | W19: 1.55 | X19: =SUM(W19-J19) | Y19: =SUM(X19*1/W19) | Z19: =SUM(C19*X19)
A20: COP 20 | B20: DEMONTARE CABLU DIN CANALIZARE MAI MARE SAU EGAL DE 600/0.6 | C20: =SUM(D20:I20) | D20: =SUM(C56) | E20: =SUM(C88) | F20: =SUM(C120) | G20: =SUM(C152) | H20: =SUM(C184) | I20: =SUM(C216) | J20: 0.51 | K20: =SUM(C20*J20) | O20: =SUM(D20*2) | P20: =SUM(E20*2) | Q20: =SUM(F20*2) | R20: =SUM(G20*2) | S20: =SUM(H20*2) | T20: =SUM(I20*2) | W20: 0.61 | X20: =SUM(W20-J20) | Y20: =SUM(X20*1/W20) | Z20: =SUM(C20*X20)
A21: COP 21 | B21: Vidanjare camine | C21: =SUM(D21:I21) | D21: =SUM(C57) | E21: =SUM(C89) | F21: =SUM(C121) | G21: =SUM(C153) | H21: =SUM(C185) | I21: =SUM(C217) | J21: 6.62 | K21: =SUM(C21*J21) | W21: 7.87 | X21: =SUM(W21-J21) | Y21: =SUM(X21*1/W21) | Z21: =SUM(C21*X21)
A22: COP 23 | B22: Asistenta Tehnica (echipa 2 tehnicieni) | C22: =SUM(D22:I22) | D22: =SUM(C58) | E22: =SUM(C90) | F22: =SUM(C122) | G22: =SUM(C154) | H22: =SUM(C186) | I22: =SUM(C218) | J22: 32 | K22: =SUM(C22*J22) | W22: 38 | X22: =SUM(W22-J22) | Y22: =SUM(X22*1/W22) | Z22: =SUM(C22*X22)
A23: COP 24 | B23: INCHIRIERE BULDOEXCAVATOR SAU UTILAJ | C23: =SUM(D23:I23) | D23: =SUM(C59) | E23: =SUM(C91) | F23: =SUM(C123) | G23: =SUM(C155) | H23: =SUM(C187) | I23: =SUM(C219) | J23: 31.31 | K23: =SUM(C23*J23) | W23: 37.18 | X23: =SUM(W23-J23) | Y23: =SUM(X23*1/W23) | Z23: =SUM(C23*X23)
A24: COP 26 | B24: Inchiriere TIR cu ora ( pentru perioada de stationare pana la incarcarea completa) | C24: =SUM(D24:I24) | D24: =SUM(C60) | E24: =SUM(C92) | F24: =SUM(C124) | G24: =SUM(C156) | H24: =SUM(C188) | I24: =SUM(C220) | J24: 13.87 | K24: =SUM(C24*J24) | N24: AERIAN : RURAL | W24: 16.47 | X24: =SUM(W24-J24) | Y24: =SUM(X24*1/W24) | Z24: =SUM(C24*X24)
A25: COP 27 | B25: DEMONTARE CABLU + STREANG | C25: =SUM(D25:I25) | D25: =SUM(C61) | E25: =SUM(C93) | F25: =SUM(C125) | G25: =SUM(C157) | H25: =SUM(C189) | I25: =SUM(C221) | J25: 0.19 | K25: =SUM(C25*J25) | O25: =SUM(D25*1.2) | P25: =SUM(E25*1.2) | Q25: =SUM(F25*1.2) | R25: =SUM(G25*1.2) | S25: =SUM(H25*1.2) | T25: =SUM(I25*1.2) | W25: 0.23 | X25: =SUM(W25-J25) | Y25: =SUM(X25*1/W25) | Z25: =SUM(C25*X25)
A26: COP 28 | B26: DEMONTARE CABLU + BRIDA SAU STREANG + BRIDA | C26: =SUM(D26:I26) | D26: =SUM(C62) | E26: =SUM(C94) | F26: =SUM(C126) | G26: =SUM(C158) | H26: =SUM(C190) | I26: =SUM(C222) | J26: 0.16 | K26: =SUM(C26*J26) | M26: Zile lucrate | N26: 5 | O26: =SUM(D26*1.1) | P26: =SUM(E26*1.1) | Q26: =SUM(F26*1.1) | R26: =SUM(G26*1.1) | S26: =SUM(H26*1.1) | T26: =SUM(I26*1.1) | W26: 0.2 | X26: =SUM(W26-J26) | Y26: =SUM(X26*1/W26) | Z26: =SUM(C26*X26)
A27: COP 29 | B27: DEMONTARE CABLU + STREANG + BRIDA | C27: =SUM(D27:I27) | D27: =SUM(C63) | E27: =SUM(C95) | F27: =SUM(C127) | G27: =SUM(C159) | H27: =SUM(C191) | I27: =SUM(C223) | J27: 0.28 | K27: =SUM(C27*J27) | M27: Persoane Media saptamanala | N27: =SUM((D66+D98+D130+D162+D194)/N26) | O27: =SUM(D27*2) | P27: =SUM(E27*2) | Q27: =SUM(F27*2) | R27: =SUM(G27*2) | S27: =SUM(H27*2) | T27: =SUM(I27*2) | W27: 0.34 | X27: =SUM(W27-J27) | Y27: =SUM(X27*1/W27) | Z27: =SUM(C27*X27)
J28: TOTAL EURO | K28: =SUM(K3:K27) | N28: TOTAL ml / zi | O28: =SUM(O3:O27) | P28: =SUM(P3:P27) | Q28: =SUM(Q3:Q27) | R28: =SUM(R3:R27) | S28: =SUM(S3:S27) | T28: =SUM(T3:T27) | W28: TOTAL ADAOS | Z28: =SUM(Z3:Z27)
J29: CURS EURO | K29: 5.2 | N29: TOTAL ml / pers. | O29: =SUM(O28/D66) | P29: =SUM(P28/D98) | Q29: =SUM(Q28/D130) | R29: =SUM(R28/D162) | S29: =SUM(S28/D194) | T29: =SUM(T28/D226)
J30: TOTAL RON | K30: =SUM(K29*K28)
J31: TVA | K31: =SUM(K30*0.21) | N31: Media zil. sapt. / pers. | O31: =SUM(O29+P29+Q29+R29+S29)/ N26
J32: TOTAL GENERAL | K32: =SUM(K30*1.21)
N34: Observatii :
B37: LUNI | C37: =SUM(D2)
A39: COP 1 | B39: EPUIZAREA MECANICA A APEI CU MOTOPOMPA | C39: =SUM(D39:X39) | D39: 0 | E39: 0 | F39: 0 | G39: 0 | H39: 0 | I39: 0 | J39: 0 | K39: 0 | L39: 0 | M39: 0 | N39: 0 | O39: 0 | P39: 0 | Q39: 0 | R39: 0 | S39: 0 | T39: 0 | U39: 0 | V39: 0 | W39: 0 | X39: 0
A40: COP 2 | B40: REFACERI PAVAJE LA STRAZI (TOATTE MATERIALELE, TRANSPORTURILE SI MANOPERA INCLUSE) | C40: =SUM(D40:X40) | D40: 0 | E40: 0 | F40: 0 | G40: 0 | H40: 0 | I40: 0 | J40: 0 | K40: 0 | L40: 0 | M40: 0 | N40: 0 | O40: 0 | P40: 0 | Q40: 0 | R40: 0 | S40: 0 | T40: 0 | U40: 0 | V40: 0 | W40: 0 | X40: 0
A41: COP 3 | B41: REFACERI PAVAJE TROTUAR, ALEI PIETONALE (TOATE MATERIALELE, TRANSPORTURILE Sl MANOPERA INCLUSE) | C41: =SUM(D41:X41) | D41: 0 | E41: 0 | F41: 0 | G41: 0 | H41: 0 | I41: 0 | J41: 0 | K41: 0 | L41: 0 | M41: 0 | N41: 0 | O41: 0 | P41: 0 | Q41: 0 | R41: 0 | S41: 0 | T41: 0 | U41: 0 | V41: 0 | W41: 0 | X41: 0
A42: COP 4 | B42: INCHIRIERE MACARA / NACELA | C42: =SUM(D42:X42) | D42: 0 | E42: 0 | F42: 0 | G42: 0 | H42: 0 | I42: 0 | J42: 0 | K42: 0 | L42: 0 | M42: 0 | N42: 0 | O42: 0 | P42: 0 | Q42: 0 | R42: 0 | S42: 0 | T42: 0 | U42: 0 | V42: 0 | W42: 0 | X42: 0
A43: COP 5 | B43: TRANSPORT MATERIALE MASINA 1.5 T | C43: =SUM(D43:X43) | D43: 0 | E43: 0 | F43: 0 | G43: 0 | H43: 0 | I43: 0 | J43: 0 | K43: 0 | L43: 0 | M43: 0 | N43: 0 | O43: 0 | P43: 0 | Q43: 0 | R43: 0 | S43: 0 | T43: 0 | U43: 0 | V43: 0 | W43: 0 | X43: 0
A44: COP 6 | B44: TRANSPORT MATERIALE MASINA 3.5 T | C44: =SUM(D44:X44) | D44: 0 | E44: 0 | F44: 0 | G44: 0 | H44: 0 | I44: 0 | J44: 0 | K44: 0 | L44: 0 | M44: 0 | N44: 0 | O44: 0 | P44: 0 | Q44: 0 | R44: 0 | S44: 0 | T44: 0 | U44: 0 | V44: 0 | W44: 0 | X44: 0
A45: COP 8 | B45: TRANSPORT MATERIALE MASINA 20 T | C45: =SUM(D45:X45) | D45: 0 | E45: 0 | F45: 0 | G45: 0 | H45: 0 | I45: 0 | J45: 0 | K45: 0 | L45: 0 | M45: 0 | N45: 0 | O45: 0 | P45: 0 | Q45: 0 | R45: 0 | S45: 0 | T45: 0 | U45: 0 | V45: 0 | W45: 0 | X45: 0
...

Sheet SHEET_GOL_2
A2: Nr. Crt | B2: Descriere articol | C2: TOTAL | D2: 46209 | E2: 46210 | F2: 46211 | G2: 46212 | H2: 46213 | I2: 46214 | J2: PRET | K2: TOTAL | W2: PRET BIS | X2: ADAOS ml | Y2: ADAOS % | Z2: ADAOS
